Workbook
Name Dash_FundingBasis: '12) Budget Line Mapping'!$M$2:$M$4
Name Dash_PeriodView: '12) Budget Line Mapping'!$L$2:$L$4
Name Dash_ReportCutOff: '1) Budget-Actuals Dashboard'!$C$4
Name WorkPackages: '12) Budget Line Mapping'!$N$2:$N$6

Sheet 0) ReadMe and Contents
A1: SHOC 2.0 (UNOFFICIAL)| UKRI Budget vs Actuals Project Dashboard
A2: Illustrative UKRI/ESRC fEC project tracker | Created by Alexander Pymm as a Proof of Concept for the RUSI OCP Project Officer Role
A4: Workbook purpose and Readme
A5: Project | B5: Strategic Hub for Organised Crime Research 2.0 (SHOC 2.0) | C5: WHAT IS THIS TOOL? In short, this workbook allows for real-time tracking of project costs against funder budgets, breaking down spend by category and forecasting areas of over and underspend (Variance Analysis). It also has capabilities to automate the import of new monthly transaction data from the accompanying .csv template, if enabled (see Tab 4).
A6: Lead Institution | B6: Royal United Services Institute (RUSI) - Organised Crime and Policing
A7: Funder | B7: Illustrative UKRI/ESRC award | C7: WHERE IS THIS DATA FROM? The Budget is a purely hypothetical example based around a typical full Economic Costing (fEC) model, alongside an 80% fEC UKRI contribution rate. The Budget is comprised of 3 Work Packages, each centered around a regional hub relevant to the OCP's recent engagement work: London (UK/Europe); Nairobi (/East Africa); and Bogota (Colombia/Latin America). Like the original SHOC project, promised outputs relate chiefly to engagement activities, such as workshops, conferences and panels, alongside broader collaborative opportunities.
A8: Project start | B8: 46113
A9: Project end | B9: 47208 | C9: IMPORTED TRANSACTIONS ARE ONLY ADDED TO THE LEDGER ONCE VERIFIED AGAINST CORRESPONDING BUDGET ITEMS A new batch remains excluded until its Refresh Log status is explicitly changed to 'APPROVED.'
A10: Reporting currency | B10: GBP
A12: Contents and Navigation
A13: Budget-vs-Actuals Dashboard | B13: Project overview: Budget, cost to date, variance, commitments and forecast, broken down by Work Package and cost category.
A14: Variance Detail | B14: Which Budget line is driving a variance, and by how much.
A15: Forecast Bridge | B15: The forecast for each budget line by Project Completion.
A16: Monthly Processes
A17: Monthly Update | B17: A step-by-step guide for updating the Dashboard with new monthly transactions.
A18: Refresh Log | B18: Provides a record of when new records have been added to the Dashboard, and which files/sources were used.
A19: Key Records
A20: Actuals Ledger | B20: Records all confirmed (personally verified) transactions contributing to the Directly Incurred costs on the project (e.g. Conference material, travel expenses and reimbursements etc.)
A21: Allocations | B21: Allocated Costs recorded against the project Budget. Includes allocated staff, estates and indirect costs (separate from directly incurred transaction/invoice costs).
A22: Commitments Forecast | B22: Open purchase orders and contracts (money committed but not yet spent)
A23: Back-end & Validation
A24: Budget Baseline | B24: The version of the Budget approved by the funder. The baseline reference against future project pending.
A25: Budget Changes | B25: Dated, approved changes to the original budget
A26: Model Checks | B26: A series of validity checks to check against common compliance issues or trechnical errors in the Excel file.
A27: Mappings
A29: Monthly Transaction Updates: Step-by-Step Process
A30: 1 | B30: Open and review the dashboard for currency | C30: After saving the Dashboard somewhere appropriate, it is recommended to check a few things to make sure you get the most out of the Dashboard: i) check the 'reporting cut-off' and 'last approved refresh' dates to make sure your data is up-to-date; and ii) check the model status indicator for existing errors.
A31: 2 | B31: Create a staged batch | C31: Add a 'STAGED' row on Refresh Log, alongside: i) a unique Batch ID; ii) an expected row count; and iii) a source control total.
A32: 3 | B32: Bring in transactions [manual/offline approach] | C32: Paste values into the blue input columns on the Actuals Ledger. Background route: follow the Monthly Update sheet to configure the optional Power Query staging import, then refresh it explicitly.
A33: 4 | B33: Validate | C33: Resolve every staging/ledger issue: schema, dates, amount, unique ID, mapping, evidence and reversal link. Reconcile rows and value to the source total.
A34: 5 | B34: Approve | C34: Only after review, change the batch status from STAGED to APPROVED. The dashboard will then include the batch.
A35: 6 | B35: Update exposure | C35: Update Allocations and Commitments separately. Review Forecast at Completion and the Checks sheet.
A36: 7 | B36: Close and save | C36: Set the Dashboard cut-off to the reviewed month-end, confirm PASS, record reviewer/source notes and save the monthly state.
A38: Dashboard Terms
A39: Term | B39: Definition | C39: Included in realised/recognised cost? | D39: Control treatment
A40: Original Budget | B40: Frozen accepted Budget at 100% fEC, with UKRI and RUSI shares retained. | C40: No: comparator | D40: Never overwritten
A41: Approved Budget | B41: Original Budget plus any subsequent authorised changes. | C41: No: comparator | D41: Changes recorded separately
A42: Confirmed DI Costs | B42: Confirmed, auditable project-identifiable transaction at booked GBP value. | C42: Yes | D42: Evidence, dates, mapping and duplicate tests
A43: Confirmed DA Costs | B43: Recorded DA staff, estate or indirect management allocation. Often not charged against the project like DI costs (e.g by invoice or Tx) | C43: Yes, shown separately | D43: Allocation basis and source required
A44: Committed Costs | B44: Payments liable for payment but not yet realised. (e.g. open purchase orders, contracts or other future exposures) | C44: No | D44: Separate ledger. Status must be Open
...

Sheet 1) Budget-Actuals Dashboard
A1: SHOC 2.0 | Budget vs Actuals Dashboard
A2: Illustrative UKRI/ESRC fEC project
A3: ="Illustrative portfolio data | As of "&TEXT(C4,"dd mmm yyyy")&" | Last approved refresh "&TEXT('14) Model Calc'!B27,"dd mmm yyyy hh:mm")&" | Model status "&'11) Model Audit Checks'!B2 -> Illustrative portfolio data | As of 31 Aug 2026 | Last approved refresh 01 Sep 2026 09:00 | Model status PASS
A4: Reporting cut-off | C4: 46265 | E4: Period view | G4: Cumulative | I4: Funding basis | K4: 100% fEC | M4: ='11) Model Audit Checks'!$B$2 -> PASS
A5: Work Package | C5: All | E5: fEC Heading | G5: Directly Incurred | I5: fEC Subheading | K5: All
A7: Phased Budget | D7: Confirmed Cost | G7: Variance to phased | J7: Open Commitments | M7: Forecast at Completion
A8: ='14) Model Calc'!B12 -> 12805.558 | D8: ='14) Model Calc'!B13 -> 13751.2 | G8: ='14) Model Calc'!B14 -> -945.64167 | J8: ='14) Model Calc'!B19 -> 27200 | M8: ='14) Model Calc'!B20 -> 157100.02
A10: Selected-period approved Budget | D10: Realised and verified DI + DA costs | G10: Budget minus confirmed; timing is not automatically favourable | J10: Future comittments (excluded from actuals) | M10: =IF('14) Model Calc'!B21<0,"Forecast is "&TEXT(ABS('14) Model Calc'!B21),"£#,##0")&" above approved Budget","Forecast is within approved Budget") -> Forecast is £2,900 above approved Budget
A25: DI measure
A26: Confirmed DI Costs | D26: ='14) Model Calc'!B22 -> 13751.2
A27: Remaining DI Budget | D27: ='14) Model Calc'!B24 -> 140448.82
A28: Budget consumed | D28: ='14) Model Calc'!B25 -> 0.08917768
A30: Selected-period position by Work Package | I30: Selected-period position by fEC Heading
A31: ='14) Model Calc'!A76 -> Work Package | B31: ='14) Model Calc'!B76 -> Selected-period Budget | C31: ='14) Model Calc'!C76 -> Recognised cost | D31: ='14) Model Calc'!D76 -> Variance | E31: ='14) Model Calc'!E76 -> Open commitments | F31: ='14) Model Calc'!F76 -> Forecast at Completion | G31: ='14) Model Calc'!G76 -> Full approved Budget | I31: ='14) Model Calc'!I76 -> fEC Heading | J31: ='14) Model Calc'!J76 -> Selected-period Budget | K31: ='14) Model Calc'!K76 -> Recognised cost | L31: ='14) Model Calc'!L76 -> Variance | M31: ='14) Model Calc'!M76 -> Open commitments | N31: ='14) Model Calc'!N76 -> Forecast at Completion | O31: ='14) Model Calc'!O76 -> Full approved Budget
A32: ='14) Model Calc'!A77 -> WP1 | B32: ='14) Model Calc'!B77 -> 15804.271 | C32: ='14) Model Calc'!C77 -> 16853.15 | D32: ='14) Model Calc'!D77 -> -1048.8792 | E32: ='14) Model Calc'!E77 -> 16350 | F32: ='14) Model Calc'!F77 -> 153817.23 | G32: ='14) Model Calc'!G77 -> 152117.23 | I32: ='14) Model Calc'!I77 -> Directly Allocated | J32: ='14) Model Calc'!J77 -> 10948.283 | K32: ='14) Model Calc'!K77 -> 10882.64 | L32: ='14) Model Calc'!L77 -> 65.643333 | M32: ='14) Model Calc'!M77 -> 0 | N32: ='14) Model Calc'!N77 -> 82553.88 | O32: ='14) Model Calc'!O77 -> 82553.88
A33: ='14) Model Calc'!A78 -> WP2 | B33: ='14) Model Calc'!B78 -> 8401.3125 | C33: ='14) Model Calc'!C78 -> 8380.3 | D33: ='14) Model Calc'!D78 -> 21.0125 | E33: ='14) Model Calc'!E78 -> 5300 | F33: ='14) Model Calc'!F78 -> 76939.45 | G33: ='14) Model Calc'!G78 -> 76489.45 | I33: ='14) Model Calc'!I78 -> Directly Incurred | J33: ='14) Model Calc'!J78 -> 12805.558 | K33: ='14) Model Calc'!K78 -> 13751.2 | L33: ='14) Model Calc'!L78 -> -945.64167 | M33: ='14) Model Calc'!M78 -> 27200 | N33: ='14) Model Calc'!N78 -> 157100.02 | O33: ='14) Model Calc'!O78 -> 154200.02
A34: ='14) Model Calc'!A79 -> WP3 | B34: ='14) Model Calc'!B79 -> 10569.667 | C34: ='14) Model Calc'!C79 -> 10355.67 | D34: ='14) Model Calc'!D79 -> 213.99667 | E34: ='14) Model Calc'!E79 -> 5550 | F34: ='14) Model Calc'!F79 -> 92851.6 | G34: ='14) Model Calc'!G79 -> 92101.6 | I34: ='14) Model Calc'!I79 -> Indirect | J34: ='14) Model Calc'!J79 -> 11021.408 | K34: ='14) Model Calc'!K79 -> 10955.28 | L34: ='14) Model Calc'!L79 -> 66.128333 | M34: ='14) Model Calc'!M79 -> 0 | N34: ='14) Model Calc'!N79 -> 83954.38 | O34: ='14) Model Calc'!O79 -> 83954.38
A35: ='14) Model Calc'!A80 -> Total | B35: ='14) Model Calc'!B80 -> 34775.25 | C35: ='14) Model Calc'!C80 -> 35589.12 | D35: ='14) Model Calc'!D80 -> -813.87 | E35: ='14) Model Calc'!E80 -> 27200 | F35: ='14) Model Calc'!F80 -> 323608.28 | G35: ='14) Model Calc'!G80 -> 320708.28 | I35: ='14) Model Calc'!I80 -> Total | J35: ='14) Model Calc'!J80 -> 34775.25 | K35: ='14) Model Calc'!K80 -> 35589.12 | L35: ='14) Model Calc'!L80 -> -813.87 | M35: ='14) Model Calc'!M80 -> 27200 | N35: ='14) Model Calc'!N80 -> 323608.28 | O35: ='14) Model Calc'!O80 -> 320708.28
A36: ="Management reading: recognised cost is "&TEXT('14) Model Calc'!B16,"£#,##0")&" against cumulative phased Budget of "&TEXT('14) Model Calc'!B15,"£#,##0")&" and simple pro-rata of "&TEXT('14) Model Calc'!B17,"£#,##0")&". Open commitments are shown separately." -> Management reading: recognised cost is £13,751 against cumulative phased Budget of £12,806 and simple pro-rata of £21,417. Open commitments are shown separately.

Sheet 2) Variance Detail
A1: Variance and exposure detail
A2: Budget-item drill-down using the Dashboard reporting cut-off, period view and funding basis
A4: ="Current view: "&'1) Budget-Actuals Dashboard'!$G$4&" | "&'1) Budget-Actuals Dashboard'!$K$4&" | cut-off "&TEXT('1) Budget-Actuals Dashboard'!$C$4,"dd mmm yyyy")&" | WP "&'1) Budget-Actuals Dashboard'!$C$5&" | heading "&'1) Budget-Actuals Dashboard'!$G$5&" | subheading "&'1) Budget-Actuals Dashboard'!$K$5 -> Current view: Cumulative | 100% fEC | cut-off 31 Aug 2026 | WP All | heading Directly Incurred | subheading All
A7: Budget Item ID | B7: Description | C7: Work Package | D7: fEC Heading | E7: fEC Subheading | F7: Reporting Category | G7: In Selected Scope? | H7: Period Budget | I7: Period Recognised | J7: Variance £ | K7: Variance % | L7: Open Commitments | M7: FAC Variance
A8: WP1_S01 | B8: RUSI - Project Officer (existing staff, DA) @GrB/4 | C8: WP1 | D8: Directly Allocated | E8: Staff | F8: Directly Allocated Staff | G8: =IF(AND(OR('1) Budget-Actuals Dashboard'!$C$5="All",C8='1) Budget-Actuals Dashboard'!$C$5),OR('1) Budget-Actuals Dashboard'!$G$5="All",D8='1) Budget-Actuals Dashboard'!$G$5),OR('1) Budget-Actuals Dashboard'!$K$5="All",E8='1) Budget-Actuals Dashboard'!$K$5)),"Yes","No") -> No | H8: =IF('1) Budget-Actuals Dashboard'!$K$4="100% fEC",SUMIFS('9) Budget Baseline'!$P$8:$P$1087,'9) Budget Baseline'!$B$8:$B$1087,A8,'9) Budget Baseline'!$H$8:$H$1087,">="&'14) Model Calc'!$B$9,'9) Budget Baseline'!$H$8:$H$1087,"<="&'14) Model Calc'!$B$10),IF('1) Budget-Actuals Dashboard'!$K$4="UKRI",SUMIFS('9) Budget Baseline'!$Q$8:$Q$1087,'9) Budget Baseline'!$B$8:$B$1087,A8,'9) Budget Baseline'!$H$8:$H$1087,">="&'14) Model Calc'!$B$9,'9) Budget Baseline'!$H$8:$H$1087,"<="&'14) Model Calc'!$B$10),SUMIFS('9) Budget Baseline'!$R$8:$R$1087,'9) Budget Baseline'!$B$8:$B$1087,A8,'9) Budget Baseline'!$H$8:$H$1087,">="&'14) Model Calc'!$B$9,'9) Budget Baseline'!$H$8:$H$1087,"<="&'14) Model Calc'!$B$10))) -> 1635.4167 | I8: =IF('1) Budget-Actuals Dashboard'!$K$4="100% fEC",SUMIFS('6) Actuals Ledger - DI Costs'!$R$8:$R$2007,'6) Actuals Ledger - DI Costs'!$G$8:$G$2007,A8,'6) Actuals Ledger - DI Costs'!$C$8:$C$2007,">="&'14) Model Calc'!$B$9,'6) Actuals Ledger - DI Costs'!$C$8:$C$2007,"<="&'14) Model Calc'!$B$10)+SUMIFS('7) Allocations - DA Costs'!$O$8:$O$2007,'7) Allocations - DA Costs'!$D$8:$D$2007,A8,'7) Allocations - DA Costs'!$C$8:$C$2007,">="&'14) Model Calc'!$B$9,'7) Allocations - DA Costs'!$C$8:$C$2007,"<="&'14) Model Calc'!$B$10),IF('1) Budget-Actuals Dashboard'!$K$4="UKRI",SUMIFS('6) Actuals Ledger - DI Costs'!$S$8:$S$2007,'6) Actuals Ledger - DI Costs'!$G$8:$G$2007,A8,'6) Actuals Ledger - DI Costs'!$C$8:$C$2007,">="&'14) Model Calc'!$B$9,'6) Actuals Ledger - DI Costs'!$C$8:$C$2007,"<="&'14) Model Calc'!$B$10)+SUMIFS('7) Allocations - DA Costs'!$P$8:$P$2007,'7) Allocations - DA Costs'!$D$8:$D$2007,A8,'7) Allocations - DA Costs'!$C$8:$C$2007,">="&'14) Model Calc'!$B$9,'7) Allocations - DA Costs'!$C$8:$C$2007,"<="&'14) Model Calc'!$B$10),SUMIFS('6) Actuals Ledger - DI Costs'!$T$8:$T$2007,'6) Actuals Ledger - DI Costs'!$G$8:$G$2007,A8,'6) Actuals Ledger - DI Costs'!$C$8:$C$2007,">="&'14) Model Calc'!$B$9,'6) Actuals Ledger - DI Costs'!$C$8:$C$2007,"<="&'14) Model Calc'!$B$10)+SUMIFS('7) Allocations - DA Costs'!$Q$8:$Q$2007,'7) Allocations - DA Costs'!$D$8:$D$2007,A8,'7) Allocations - DA Costs'!$C$8:$C$2007,">="&'14) Model Calc'!$B$9,'7) Allocations - DA Costs'!$C$8:$C$2007,"<="&'14) Model Calc'!$B$10))) -> 1625.59 | J8: =H8-I8 -> 9.8266667 | K8: =IF(H8=0,"",J8/H8) -> 0.0060086624 | L8: =IF('1) Budget-Actuals Dashboard'!$K$4="100% fEC",SUMIFS('8) Commitments Forecast'!$Q$8:$Q$507,'8) Commitments Forecast'!$H$8:$H$507,A8),IF('1) Budget-Actuals Dashboard'!$K$4="UKRI",SUMIFS('8) Commitments Forecast'!$R$8:$R$507,'8) Commitments Forecast'!$H$8:$H$507,A8),SUMIFS('8) Commitments Forecast'!$S$8:$S$507,'8) Commitments Forecast'!$H$8:$H$507,A8))) -> 0 | M8: =IFERROR(IF('1) Budget-Actuals Dashboard'!$K$4="100% fEC",INDEX('3) Forecast Bridge'!$L$8:$L$37,MATCH(A8,'3) Forecast Bridge'!$A$8:$A$37,0)),IF('1) Budget-Actuals Dashboard'!$K$4="UKRI",INDEX('3) Forecast Bridge'!$P$8:$P$37,MATCH(A8,'3) Forecast Bridge'!$A$8:$A$37,0)),INDEX('3) Forecast Bridge'!$Q$8:$Q$37,MATCH(A8,'3) Forecast Bridge'!$A$8:$A$37,0)))),0) -> 0
A9: WP1_S02 | B9: RUSI - Research Analyst (existing staff, DA) @GrC/8 | C9: WP1 | D9: Directly Allocated | E9: Staff | F9: Directly Allocated Staff | G9: =IF(AND(OR('1) Budget-Actuals Dashboard'!$C$5="All",C9='1) Budget-Actuals Dashboard'!$C$5),OR('1) Budget-Actuals Dashboard'!$G$5="All",D9='1) Budget-Actuals Dashboard'!$G$5),OR('1) Budget-Actuals Dashboard'!$K$5="All",E9='1) Budget-Actuals Dashboard'!$K$5)),"Yes","No") -> No | H9: =IF('1) Budget-Actuals Dashboard'!$K$4="100% fEC",SUMIFS('9) Budget Baseline'!$P$8:$P$1087,'9) Budget Baseline'!$B$8:$B$1087,A9,'9) Budget Baseline'!$H$8:$H$1087,">="&'14) Model Calc'!$B$9,'9) Budget Baseline'!$H$8:$H$1087,"<="&'14) Model Calc'!$B$10),IF('1) Budget-Actuals Dashboard'!$K$4="UKRI",SUMIFS('9) Budget Baseline'!$Q$8:$Q$1087,'9) Budget Baseline'!$B$8:$B$1087,A9,'9) Budget Baseline'!$H$8:$H$1087,">="&'14) Model Calc'!$B$9,'9) Budget Baseline'!$H$8:$H$1087,"<="&'14) Model Calc'!$B$10),SUMIFS('9) Budget Baseline'!$R$8:$R$1087,'9) Budget Baseline'!$B$8:$B$1087,A9,'9) Budget Baseline'!$H$8:$H$1087,">="&'14) Model Calc'!$B$9,'9) Budget Baseline'!$H$8:$H$1087,"<="&'14) Model Calc'!$B$10))) -> 1809.375 | I9: =IF('1) Budget-Actuals Dashboard'!$K$4="100% fEC",SUMIFS('6) Actuals Ledger - DI Costs'!$R$8:$R$2007,'6) Actuals Ledger - DI Costs'!$G$8:$G$2007,A9,'6) Actuals Ledger - DI Costs'!$C$8:$C$2007,">="&'14) Model Calc'!$B$9,'6) Actuals Ledger - DI Costs'!$C$8:$C$2007,"<="&'14) Model Calc'!$B$10)+SUMIFS('7) Allocations - DA Costs'!$O$8:$O$2007,'7) Allocations - DA Costs'!$D$8:$D$2007,A9,'7) Allocations - DA Costs'!$C$8:$C$2007,">="&'14) Model Calc'!$B$9,'7) Allocations - DA Costs'!$C$8:$C$2007,"<="&'14) Model Calc'!$B$10),IF('1) Budget-Actuals Dashboard'!$K$4="UKRI",SUMIFS('6) Actuals Ledger - DI Costs'!$S$8:$S$2007,'6) Actuals Ledger - DI Costs'!$G$8:$G$2007,A9,'6) Actuals Ledger - DI Costs'!$C$8:$C$2007,">="&'14) Model Calc'!$B$9,'6) Actuals Ledger - DI Costs'!$C$8:$C$2007,"<="&'14) Model Calc'!$B$10)+SUMIFS('7) Allocations - DA Costs'!$P$8:$P$2007,'7) Allocations - DA Costs'!$D$8:$D$2007,A9,'7) Allocations - DA Costs'!$C$8:$C$2007,">="&'14) Model Calc'!$B$9,'7) Allocations - DA Costs'!$C$8:$C$2007,"<="&'14) Model Calc'!$B$10),SUMIFS('6) Actuals Ledger - DI Costs'!$T$8:$T$2007,'6) Actuals Ledger - DI Costs'!$G$8:$G$2007,A9,'6) Actuals Ledger - DI Costs'!$C$8:$C$2007,">="&'14) Model Calc'!$B$9,'6) Actuals Ledger - DI Costs'!$C$8:$C$2007,"<="&'14) Model Calc'!$B$10)+SUMIFS('7) Allocations - DA Costs'!$Q$8:$Q$2007,'7) Allocations - DA Costs'!$D$8:$D$2007,A9,'7) Allocations - DA Costs'!$C$8:$C$2007,">="&'14) Model Calc'!$B$9,'7) Allocations - DA Costs'!$C$8:$C$2007,"<="&'14) Model Calc'!$B$10))) -> 1798.53 | J9: =H9-I9 -> 10.845 | K9: =IF(H9=0,"",J9/H9) -> 0.0059937824 | L9: =IF('1) Budget-Actuals Dashboard'!$K$4="100% fEC",SUMIFS('8) Commitments Forecast'!$Q$8:$Q$507,'8) Commitments Forecast'!$H$8:$H$507,A9),IF('1) Budget-Actuals Dashboard'!$K$4="UKRI",SUMIFS('8) Commitments Forecast'!$R$8:$R$507,'8) Commitments Forecast'!$H$8:$H$507,A9),SUMIFS('8) Commitments Forecast'!$S$8:$S$507,'8) Commitments Forecast'!$H$8:$H$507,A9))) -> 0 | M9: =IFERROR(IF('1) Budget-Actuals Dashboard'!$K$4="100% fEC",INDEX('3) Forecast Bridge'!$L$8:$L$37,MATCH(A9,'3) Forecast Bridge'!$A$8:$A$37,0)),IF('1) Budget-Actuals Dashboard'!$K$4="UKRI",INDEX('3) Forecast Bridge'!$P$8:$P$37,MATCH(A9,'3) Forecast Bridge'!$A$8:$A$37,0)),INDEX('3) Forecast Bridge'!$Q$8:$Q$37,MATCH(A9,'3) Forecast Bridge'!$A$8:$A$37,0)))),0) -> 0
A10: WP1_S03 | B10: RUSI - Programme/Project Lead (existing staff, DA) @GrE/14 | C10: WP1 | D10: Directly Allocated | E10: Staff | F10: Directly Allocated Staff | G10: =IF(AND(OR('1) Budget-Actuals Dashboard'!$C$5="All",C10='1) Budget-Actuals Dashboard'!$C$5),OR('1) Budget-Actuals Dashboard'!$G$5="All",D10='1) Budget-Actuals Dashboard'!$G$5),OR('1) Budget-Actuals Dashboard'!$K$5="All",E10='1) Budget-Actuals Dashboard'!$K$5)),"Yes","No") -> No | H10: =IF('1) Budget-Actuals Dashboard'!$K$4="100% fEC",SUMIFS('9) Budget Baseline'!$P$8:$P$1087,'9) Budget Baseline'!$B$8:$B$1087,A10,'9) Budget Baseline'!$H$8:$H$1087,">="&'14) Model Calc'!$B$9,'9) Budget Baseline'!$H$8:$H$1087,"<="&'14) Model Calc'!$B$10),IF('1) Budget-Actuals Dashboard'!$K$4="UKRI",SUMIFS('9) Budget Baseline'!$Q$8:$Q$1087,'9) Budget Baseline'!$B$8:$B$1087,A10,'9) Budget Baseline'!$H$8:$H$1087,">="&'14) Model Calc'!$B$9,'9) Budget Baseline'!$H$8:$H$1087,"<="&'14) Model Calc'!$B$10),SUMIFS('9) Budget Baseline'!$R$8:$R$1087,'9) Budget Baseline'!$B$8:$B$1087,A10,'9) Budget Baseline'!$H$8:$H$1087,">="&'14) Model Calc'!$B$9,'9) Budget Baseline'!$H$8:$H$1087,"<="&'14) Model Calc'!$B$10))) -> 1856.25 | I10: =IF('1) Budget-Actuals Dashboard'!$K$4="100% fEC",SUMIFS('6) Actuals Ledger - DI Costs'!$R$8:$R$2007,'6) Actuals Ledger - DI Costs'!$G$8:$G$2007,A10,'6) Actuals Ledger - DI Costs'!$C$8:$C$2007,">="&'14) Model Calc'!$B$9,'6) Actuals Ledger - DI Costs'!$C$8:$C$2007,"<="&'14) Model Calc'!$B$10)+SUMIFS('7) Allocations - DA Costs'!$O$8:$O$2007,'7) Allocations - DA Costs'!$D$8:$D$2007,A10,'7) Allocations - DA Costs'!$C$8:$C$2007,">="&'14) Model Calc'!$B$9,'7) Allocations - DA Costs'!$C$8:$C$2007,"<="&'14) Model Calc'!$B$10),IF('1) Budget-Actuals Dashboard'!$K$4="UKRI",SUMIFS('6) Actuals Ledger - DI Costs'!$S$8:$S$2007,'6) Actuals Ledger - DI Costs'!$G$8:$G$2007,A10,'6) Actuals Ledger - DI Costs'!$C$8:$C$2007,">="&'14) Model Calc'!$B$9,'6) Actuals Ledger - DI Costs'!$C$8:$C$2007,"<="&'14) Model Calc'!$B$10)+SUMIFS('7) Allocations - DA Costs'!$P$8:$P$2007,'7) Allocations - DA Costs'!$D$8:$D$2007,A10,'7) Allocations - DA Costs'!$C$8:$C$2007,">="&'14) Model Calc'!$B$9,'7) Allocations - DA Costs'!$C$8:$C$2007,"<="&'14) Model Calc'!$B$10),SUMIFS('6) Actuals Ledger - DI Costs'!$T$8:$T$2007,'6) Actuals Ledger - DI Costs'!$G$8:$G$2007,A10,'6) Actuals Ledger - DI Costs'!$C$8:$C$2007,">="&'14) Model Calc'!$B$9,'6) Actuals Ledger - DI Costs'!$C$8:$C$2007,"<="&'14) Model Calc'!$B$10)+SUMIFS('7) Allocations - DA Costs'!$Q$8:$Q$2007,'7) Allocations - DA Costs'!$D$8:$D$2007,A10,'7) Allocations - DA Costs'!$C$8:$C$2007,">="&'14) Model Calc'!$B$9,'7) Allocations - DA Costs'!$C$8:$C$2007,"<="&'14) Model Calc'!$B$10))) -> 1845.11 | J10: =H10-I10 -> 11.14 | K10: =IF(H10=0,"",J10/H10) -> 0.0060013468 | L10: =IF('1) Budget-Actuals Dashboard'!$K$4="100% fEC",SUMIFS('8) Commitments Forecast'!$Q$8:$Q$507,'8) Commitments Forecast'!$H$8:$H$507,A10),IF('1) Budget-Actuals Dashboard'!$K$4="UKRI",SUMIFS('8) Commitments Forecast'!$R$8:$R$507,'8) Commitments Forecast'!$H$8:$H$507,A10),SUMIFS('8) Commitments Forecast'!$S$8:$S$507,'8) Commitments Forecast'!$H$8:$H$507,A10))) -> 0 | M10: =IFERROR(IF('1) Budget-Actuals Dashboard'!$K$4="100% fEC",INDEX('3) Forecast Bridge'!$L$8:$L$37,MATCH(A10,'3) Forecast Bridge'!$A$8:$A$37,0)),IF('1) Budget-Actuals Dashboard'!$K$4="UKRI",INDEX('3) Forecast Bridge'!$P$8:$P$37,MATCH(A10,'3) Forecast Bridge'!$A$8:$A$37,0)),INDEX('3) Forecast Bridge'!$Q$8:$Q$37,MATCH(A10,'3) Forecast Bridge'!$A$8:$A$37,0)))),0) -> 0
A11: WP1_TRAVEL | B11: RUSI - UK rail, local travel and subsistence Budget | C11: WP1 | D11: Directly Incurred | E11: Travel & Subsistence | F11: Travel & Subsistence | G11: =IF(AND(OR('1) Budget-Actuals Dashboard'!$C$5="All",C11='1) Budget-Actuals Dashboard'!$C$5),OR('1) Budget-Actuals Dashboard'!$G$5="All",D11='1) Budget-Actuals Dashboard'!$G$5),OR('1) Budget-Actuals Dashboard'!$K$5="All",E11='1) Budget-Actuals Dashboard'!$K$5)),"Yes","No") -> Yes | H11: =IF('1) Budget-Actuals Dashboard'!$K$4="100% fEC",SUMIFS('9) Budget Baseline'!$P$8:$P$1087,'9) Budget Baseline'!$B$8:$B$1087,A11,'9) Budget Baseline'!$H$8:$H$1087,">="&'14) Model Calc'!$B$9,'9) Budget Baseline'!$H$8:$H$1087,"<="&'14) Model Calc'!$B$10),IF('1) Budget-Actuals Dashboard'!$K$4="UKRI",SUMIFS('9) Budget Baseline'!$Q$8:$Q$1087,'9) Budget Baseline'!$B$8:$B$1087,A11,'9) Budget Baseline'!$H$8:$H$1087,">="&'14) Model Calc'!$B$9,'9) Budget Baseline'!$H$8:$H$1087,"<="&'14) Model Calc'!$B$10),SUMIFS('9) Budget Baseline'!$R$8:$R$1087,'9) Budget Baseline'!$B$8:$B$1087,A11,'9) Budget Baseline'!$H$8:$H$1087,">="&'14) Model Calc'!$B$9,'9) Budget Baseline'!$H$8:$H$1087,"<="&'14) Model Calc'!$B$10))) -> 1041.6667 | I11: =IF('1) Budget-Actuals Dashboard'!$K$4="100% fEC",SUMIFS('6) Actuals Ledger - DI Costs'!$R$8:$R$2007,'6) Actuals Ledger - DI Costs'!$G$8:$G$2007,A11,'6) Actuals Ledger - DI Costs'!$C$8:$C$2007,">="&'14) Model Calc'!$B$9,'6) Actuals Ledger - DI Costs'!$C$8:$C$2007,"<="&'14) Model Calc'!$B$10)+SUMIFS('7) Allocations - DA Costs'!$O$8:$O$2007,'7) Allocations - DA Costs'!$D$8:$D$2007,A11,'7) Allocations - DA Costs'!$C$8:$C$2007,">="&'14) Model Calc'!$B$9,'7) Allocations - DA Costs'!$C$8:$C$2007,"<="&'14) Model Calc'!$B$10),IF('1) Budget-Actuals Dashboard'!$K$4="UKRI",SUMIFS('6) Actuals Ledger - DI Costs'!$S$8:$S$2007,'6) Actuals Ledger - DI Costs'!$G$8:$G$2007,A11,'6) Actuals Ledger - DI Costs'!$C$8:$C$2007,">="&'14) Model Calc'!$B$9,'6) Actuals Ledger - DI Costs'!$C$8:$C$2007,"<="&'14) Model Calc'!$B$10)+SUMIFS('7) Allocations - DA Costs'!$P$8:$P$2007,'7) Allocations - DA Costs'!$D$8:$D$2007,A11,'7) Allocations - DA Costs'!$C$8:$C$2007,">="&'14) Model Calc'!$B$9,'7) Allocations - DA Costs'!$C$8:$C$2007,"<="&'14) Model Calc'!$B$10),SUMIFS('6) Actuals Ledger - DI Costs'!$T$8:$T$2007,'6) Actuals Ledger - DI Costs'!$G$8:$G$2007,A11,'6) Actuals Ledger - DI Costs'!$C$8:$C$2007,">="&'14) Model Calc'!$B$9,'6) Actuals Ledger - DI Costs'!$C$8:$C$2007,"<="&'14) Model Calc'!$B$10)+SUMIFS('7) Allocations - DA Costs'!$Q$8:$Q$2007,'7) Allocations - DA Costs'!$D$8:$D$2007,A11,'7) Allocations - DA Costs'!$C$8:$C$2007,">="&'14) Model Calc'!$B$9,'7) Allocations - DA Costs'!$C$8:$C$2007,"<="&'14) Model Calc'!$B$10))) -> 1356.2 | J11: =H11-I11 -> -314.53333 | K11: =IF(H11=0,"",J11/H11) -> -0.301952 | L11: =IF('1) Budget-Actuals Dashboard'!$K$4="100% fEC",SUMIFS('8) Commitments Forecast'!$Q$8:$Q$507,'8) Commitments Forecast'!$H$8:$H$507,A11),IF('1) Budget-Actuals Dashboard'!$K$4="UKRI",SUMIFS('8) Commitments Forecast'!$R$8:$R$507,'8) Commitments Forecast'!$H$8:$H$507,A11),SUMIFS('8) Commitments Forecast'!$S$8:$S$507,'8) Commitments Forecast'!$H$8:$H$507,A11))) -> 0 | M11: =IFERROR(IF('1) Budget-Actuals Dashboard'!$K$4="100% fEC",INDEX('3) Forecast Bridge'!$L$8:$L$37,MATCH(A11,'3) Forecast Bridge'!$A$8:$A$37,0)),IF('1) Budget-Actuals Dashboard'!$K$4="UKRI",INDEX('3) Forecast Bridge'!$P$8:$P$37,MATCH(A11,'3) Forecast Bridge'!$A$8:$A$37,0)),INDEX('3) Forecast Bridge'!$Q$8:$Q$37,MATCH(A11,'3) Forecast Bridge'!$A$8:$A$37,0)))),0) -> 0
A12: WP1_CONF | B12: RUSI - five-day flagship London conferences (launch and close) | C12: WP1 | D12: Directly Incurred | E12: Other Directly Incurred | F12: Conferences | G12: =IF(AND(OR('1) Budget-Actuals Dashboard'!$C$5="All",C12='1) Budget-Actuals Dashboard'!$C$5),OR('1) Budget-Actuals Dashboard'!$G$5="All",D12='1) Budget-Actuals Dashboard'!$G$5),OR('1) Budget-Actuals Dashboard'!$K$5="All",E12='1) Budget-Actuals Dashboard'!$K$5)),"Yes","No") -> Yes | H12: =IF('1) Budget-Actuals Dashboard'!$K$4="100% fEC",SUMIFS('9) Budget Baseline'!$P$8:$P$1087,'9) Budget Baseline'!$B$8:$B$1087,A12,'9) Budget Baseline'!$H$8:$H$1087,">="&'14) Model Calc'!$B$9,'9) Budget Baseline'!$H$8:$H$1087,"<="&'14) Model Calc'!$B$10),IF('1) Budget-Actuals Dashboard'!$K$4="UKRI",SUMIFS('9) Budget Baseline'!$Q$8:$Q$1087,'9) Budget Baseline'!$B$8:$B$1087,A12,'9) Budget Baseline'!$H$8:$H$1087,">="&'14) Model Calc'!$B$9,'9) Budget Baseline'!$H$8:$H$1087,"<="&'14) Model Calc'!$B$10),SUMIFS('9) Budget Baseline'!$R$8:$R$1087,'9) Budget Baseline'!$B$8:$B$1087,A12,'9) Budget Baseline'!$H$8:$H$1087,">="&'14) Model Calc'!$B$9,'9) Budget Baseline'!$H$8:$H$1087,"<="&'14) Model Calc'!$B$10))) -> 0 | I12: =IF('1) Budget-Actuals Dashboard'!$K$4="100% fEC",SUMIFS('6) Actuals Ledger - DI Costs'!$R$8:$R$2007,'6) Actuals Ledger - DI Costs'!$G$8:$G$2007,A12,'6) Actuals Ledger - DI Costs'!$C$8:$C$2007,">="&'14) Model Calc'!$B$9,'6) Actuals Ledger - DI Costs'!$C$8:$C$2007,"<="&'14) Model Calc'!$B$10)+SUMIFS('7) Allocations - DA Costs'!$O$8:$O$2007,'7) Allocations - DA Costs'!$D$8:$D$2007,A12,'7) Allocations - DA Costs'!$C$8:$C$2007,">="&'14) Model Calc'!$B$9,'7) Allocations - DA Costs'!$C$8:$C$2007,"<="&'14) Model Calc'!$B$10),IF('1) Budget-Actuals Dashboard'!$K$4="UKRI",SUMIFS('6) Actuals Ledger - DI Costs'!$S$8:$S$2007,'6) Actuals Ledger - DI Costs'!$G$8:$G$2007,A12,'6) Actuals Ledger - DI Costs'!$C$8:$C$2007,">="&'14) Model Calc'!$B$9,'6) Actuals Ledger - DI Costs'!$C$8:$C$2007,"<="&'14) Model Calc'!$B$10)+SUMIFS('7) Allocations - DA Costs'!$P$8:$P$2007,'7) Allocations - DA Costs'!$D$8:$D$2007,A12,'7) Allocations - DA Costs'!$C$8:$C$2007,">="&'14) Model Calc'!$B$9,'7) Allocations - DA Costs'!$C$8:$C$2007,"<="&'14) Model Calc'!$B$10),SUMIFS('6) Actuals Ledger - DI Costs'!$T$8:$T$2007,'6) Actuals Ledger - DI Costs'!$G$8:$G$2007,A12,'6) Actuals Ledger - DI Costs'!$C$8:$C$2007,">="&'14) Model Calc'!$B$9,'6) Actuals Ledger - DI Costs'!$C$8:$C$2007,"<="&'14) Model Calc'!$B$10)+SUMIFS('7) Allocations - DA Costs'!$Q$8:$Q$2007,'7) Allocations - DA Costs'!$D$8:$D$2007,A12,'7) Allocations - DA Costs'!$C$8:$C$2007,">="&'14) Model Calc'!$B$9,'7) Allocations - DA Costs'!$C$8:$C$2007,"<="&'14) Model Calc'!$B$10))) -> 0 | J12: =H12-I12 -> 0 | K12: =IF(H12=0,"",J12/H12) | L12: =IF('1) Budget-Actuals Dashboard'!$K$4="100% fEC",SUMIFS('8) Commitments Forecast'!$Q$8:$Q$507,'8) Commitments Forecast'!$H$8:$H$507,A12),IF('1) Budget-Actuals Dashboard'!$K$4="UKRI",SUMIFS('8) Commitments Forecast'!$R$8:$R$507,'8) Commitments Forecast'!$H$8:$H$507,A12),SUMIFS('8) Commitments Forecast'!$S$8:$S$507,'8) Commitments Forecast'!$H$8:$H$507,A12))) -> 14700 | M12: =IFERROR(IF('1) Budget-Actuals Dashboard'!$K$4="100% fEC",INDEX('3) Forecast Bridge'!$L$8:$L$37,MATCH(A12,'3) Forecast Bridge'!$A$8:$A$37,0)),IF('1) Budget-Actuals Dashboard'!$K$4="UKRI",INDEX('3) Forecast Bridge'!$P$8:$P$37,MATCH(A12,'3) Forecast Bridge'!$A$8:$A$37,0)),INDEX('3) Forecast Bridge'!$Q$8:$Q$37,MATCH(A12,'3) Forecast Bridge'!$A$8:$A$37,0)))),0) -> -1800
A13: WP1_WORKSHOP | B13: RUSI - UK national and regional workshops | C13: WP1 | D13: Directly Incurred | E13: Other Directly Incurred | F13: Workshops | G13: =IF(AND(OR('1) Budget-Actuals Dashboard'!$C$5="All",C13='1) Budget-Actuals Dashboard'!$C$5),OR('1) Budget-Actuals Dashboard'!$G$5="All",D13='1) Budget-Actuals Dashboard'!$G$5),OR('1) Budget-Actuals Dashboard'!$K$5="All",E13='1) Budget-Actuals Dashboard'!$K$5)),"Yes","No") -> Yes | H13: =IF('1) Budget-Actuals Dashboard'!$K$4="100% fEC",SUMIFS('9) Budget Baseline'!$P$8:$P$1087,'9) Budget Baseline'!$B$8:$B$1087,A13,'9) Budget Baseline'!$H$8:$H$1087,">="&'14) Model Calc'!$B$9,'9) Budget Baseline'!$H$8:$H$1087,"<="&'14) Model Calc'!$B$10),IF('1) Budget-Actuals Dashboard'!$K$4="UKRI",SUMIFS('9) Budget Baseline'!$Q$8:$Q$1087,'9) Budget Baseline'!$B$8:$B$1087,A13,'9) Budget Baseline'!$H$8:$H$1087,">="&'14) Model Calc'!$B$9,'9) Budget Baseline'!$H$8:$H$1087,"<="&'14) Model Calc'!$B$10),SUMIFS('9) Budget Baseline'!$R$8:$R$1087,'9) Budget Baseline'!$B$8:$B$1087,A13,'9) Budget Baseline'!$H$8:$H$1087,">="&'14) Model Calc'!$B$9,'9) Budget Baseline'!$H$8:$H$1087,"<="&'14) Model Calc'!$B$10))) -> 1666.6667 | I13: =IF('1) Budget-Actuals Dashboard'!$K$4="100% fEC",SUMIFS('6) Actuals Ledger - DI Costs'!$R$8:$R$2007,'6) Actuals Ledger - DI Costs'!$G$8:$G$2007,A13,'6) Actuals Ledger - DI Costs'!$C$8:$C$2007,">="&'14) Model Calc'!$B$9,'6) Actuals Ledger - DI Costs'!$C$8:$C$2007,"<="&'14) Model Calc'!$B$10)+SUMIFS('7) Allocations - DA Costs'!$O$8:$O$2007,'7) Allocations - DA Costs'!$D$8:$D$2007,A13,'7) Allocations - DA Costs'!$C$8:$C$2007,">="&'14) Model Calc'!$B$9,'7) Allocations - DA Costs'!$C$8:$C$2007,"<="&'14) Model Calc'!$B$10),IF('1) Budget-Actuals Dashboard'!$K$4="UKRI",SUMIFS('6) Actuals Ledger - DI Costs'!$S$8:$S$2007,'6) Actuals Ledger - DI Costs'!$G$8:$G$2007,A13,'6) Actuals Ledger - DI Costs'!$C$8:$C$2007,">="&'14) Model Calc'!$B$9,'6) Actuals Ledger - DI Costs'!$C$8:$C$2007,"<="&'14) Model Calc'!$B$10)+SUMIFS('7) Allocations - DA Costs'!$P$8:$P$2007,'7) Allocations - DA Costs'!$D$8:$D$2007,A13,'7) Allocations - DA Costs'!$C$8:$C$2007,">="&'14) Model Calc'!$B$9,'7) Allocations - DA Costs'!$C$8:$C$2007,"<="&'14) Model Calc'!$B$10),SUMIFS('6) Actuals Ledger - DI Costs'!$T$8:$T$2007,'6) Actuals Ledger - DI Costs'!$G$8:$G$2007,A13,'6) Actuals Ledger - DI Costs'!$C$8:$C$2007,">="&'14) Model Calc'!$B$9,'6) Actuals Ledger - DI Costs'!$C$8:$C$2007,"<="&'14) Model Calc'!$B$10)+SUMIFS('7) Allocations - DA Costs'!$Q$8:$Q$2007,'7) Allocations - DA Costs'!$D$8:$D$2007,A13,'7) Allocations - DA Costs'!$C$8:$C$2007,">="&'14) Model Calc'!$B$9,'7) Allocations - DA Costs'!$C$8:$C$2007,"<="&'14) Model Calc'!$B$10))) -> 2150 | J13: =H13-I13 -> -483.33333 | K13: =IF(H13=0,"",J13/H13) -> -0.29 | L13: =IF('1) Budget-Actuals Dashboard'!$K$4="100% fEC",SUMIFS('8) Commitments Forecast'!$Q$8:$Q$507,'8) Commitments Forecast'!$H$8:$H$507,A13),IF('1) Budget-Actuals Dashboard'!$K$4="UKRI",SUMIFS('8) Commitments Forecast'!$R$8:$R$507,'8) Commitments Forecast'!$H$8:$H$507,A13),SUMIFS('8) Commitments Forecast'!$S$8:$S$507,'8) Commitments Forecast'!$H$8:$H$507,A13))) -> 1200 | M13: =IFERROR(IF('1) Budget-Actuals Dashboard'!$K$4="100% fEC",INDEX('3) Forecast Bridge'!$L$8:$L$37,MATCH(A13,'3) Forecast Bridge'!$A$8:$A$37,0)),IF('1) Budget-Actuals Dashboard'!$K$4="UKRI",INDEX('3) Forecast Bridge'!$P$8:$P$37,MATCH(A13,'3) Forecast Bridge'!$A$8:$A$37,0)),INDEX('3) Forecast Bridge'!$Q$8:$Q$37,MATCH(A13,'3) Forecast Bridge'!$A$8:$A$37,0)))),0) -> 0
A14: WP1_PANEL | B14: RUSI - hybrid panels and practitioner roundtables | C14: WP1 | D14: Directly Incurred | E14: Other Directly Incurred | F14: Panels & Roundtables | G14: =IF(AND(OR('1) Budget-Actuals Dashboard'!$C$5="All",C14='1) Budget-Actuals Dashboard'!$C$5),OR('1) Budget-Actuals Dashboard'!$G$5="All",D14='1) Budget-Actuals Dashboard'!$G$5),OR('1) Budget-Actuals Dashboard'!$K$5="All",E14='1) Budget-Actuals Dashboard'!$K$5)),"Yes","No") -> Yes | H14: =IF('1) Budget-Actuals Dashboard'!$K$4="100% fEC",SUMIFS('9) Budget Baseline'!$P$8:$P$1087,'9) Budget Baseline'!$B$8:$B$1087,A14,'9) Budget Baseline'!$H$8:$H$1087,">="&'14) Model Calc'!$B$9,'9) Budget Baseline'!$H$8:$H$1087,"<="&'14) Model Calc'!$B$10),IF('1) Budget-Actuals Dashboard'!$K$4="UKRI",SUMIFS('9) Budget Baseline'!$Q$8:$Q$1087,'9) Budget Baseline'!$B$8:$B$1087,A14,'9) Budget Baseline'!$H$8:$H$1087,">="&'14) Model Calc'!$B$9,'9) Budget Baseline'!$H$8:$H$1087,"<="&'14) Model Calc'!$B$10),SUMIFS('9) Budget Baseline'!$R$8:$R$1087,'9) Budget Baseline'!$B$8:$B$1087,A14,'9) Budget Baseline'!$H$8:$H$1087,">="&'14) Model Calc'!$B$9,'9) Budget Baseline'!$H$8:$H$1087,"<="&'14) Model Calc'!$B$10))) -> 625 | I14: =IF('1) Budget-Actuals Dashboard'!$K$4="100% fEC",SUMIFS('6) Actuals Ledger - DI Costs'!$R$8:$R$2007,'6) Actuals Ledger - DI Costs'!$G$8:$G$2007,A14,'6) Actuals Ledger - DI Costs'!$C$8:$C$2007,">="&'14) Model Calc'!$B$9,'6) Actuals Ledger - DI Costs'!$C$8:$C$2007,"<="&'14) Model Calc'!$B$10)+SUMIFS('7) Allocations - DA Costs'!$O$8:$O$2007,'7) Allocations - DA Costs'!$D$8:$D$2007,A14,'7) Allocations - DA Costs'!$C$8:$C$2007,">="&'14) Model Calc'!$B$9,'7) Allocations - DA Costs'!$C$8:$C$2007,"<="&'14) Model Calc'!$B$10),IF('1) Budget-Actuals Dashboard'!$K$4="UKRI",SUMIFS('6) Actuals Ledger - DI Costs'!$S$8:$S$2007,'6) Actuals Ledger - DI Costs'!$G$8:$G$2007,A14,'6) Actuals Ledger - DI Costs'!$C$8:$C$2007,">="&'14) Model Calc'!$B$9,'6) Actuals Ledger - DI Costs'!$C$8:$C$2007,"<="&'14) Model Calc'!$B$10)+SUMIFS('7) Allocations - DA Costs'!$P$8:$P$2007,'7) Allocations - DA Costs'!$D$8:$D$2007,A14,'7) Allocations - DA Costs'!$C$8:$C$2007,">="&'14) Model Calc'!$B$9,'7) Allocations - DA Costs'!$C$8:$C$2007,"<="&'14) Model Calc'!$B$10),SUMIFS('6) Actuals Ledger - DI Costs'!$T$8:$T$2007,'6) Actuals Ledger - DI Costs'!$G$8:$G$2007,A14,'6) Actuals Ledger - DI Costs'!$C$8:$C$2007,">="&'14) Model Calc'!$B$9,'6) Actuals Ledger - DI Costs'!$C$8:$C$2007,"<="&'14) Model Calc'!$B$10)+SUMIFS('7) Allocations - DA Costs'!$Q$8:$Q$2007,'7) Allocations - DA Costs'!$D$8:$D$2007,A14,'7) Allocations - DA Costs'!$C$8:$C$2007,">="&'14) Model Calc'!$B$9,'7) Allocations - DA Costs'!$C$8:$C$2007,"<="&'14) Model Calc'!$B$10))) -> 790 | J14: =H14-I14 -> -165 | K14: =IF(H14=0,"",J14/H14) -> -0.264 | L14: =IF('1) Budget-Actuals Dashboard'!$K$4="100% fEC",SUMIFS('8) Commitments Forecast'!$Q$8:$Q$507,'8) Commitments Forecast'!$H$8:$H$507,A14),IF('1) Budget-Actuals Dashboard'!$K$4="UKRI",SUMIFS('8) Commitments Forecast'!$R$8:$R$507,'8) Commitments Forecast'!$H$8:$H$507,A14),SUMIFS('8) Commitments Forecast'!$S$8:$S$507,'8) Commitments Forecast'!$H$8:$H$507,A14))) -> 0 | M14: =IFERROR(IF('1) Budget-Actuals Dashboard'!$K$4="100% fEC",INDEX('3) Forecast Bridge'!$L$8:$L$37,MATCH(A14,'3) Forecast Bridge'!$A$8:$A$37,0)),IF('1) Budget-Actuals Dashboard'!$K$4="UKRI",INDEX('3) Forecast Bridge'!$P$8:$P$37,MATCH(A14,'3) Forecast Bridge'!$A$8:$A$37,0)),INDEX('3) Forecast Bridge'!$Q$8:$Q$37,MATCH(A14,'3) Forecast Bridge'!$A$8:$A$37,0)))),0) -> 0
A15: WP1_COMMS | B15: RUSI - knowledge products and digital communications | C15: WP1 | D15: Directly Incurred | E15: Other Directly Incurred | F15: Communications & Knowledge Products | G15: =IF(AND(OR('1) Budget-Actuals Dashboard'!$C$5="All",C15='1) Budget-Actuals Dashboard'!$C$5),OR('1) Budget-Actuals Dashboard'!$G$5="All",D15='1) Budget-Actuals Dashboard'!$G$5),OR('1) Budget-Actuals Dashboard'!$K$5="All",E15='1) Budget-Actuals Dashboard'!$K$5)),"Yes","No") -> Yes | H15: =IF('1) Budget-Actuals Dashboard'!$K$4="100% fEC",SUMIFS('9) Budget Baseline'!$P$8:$P$1087,'9) Budget Baseline'!$B$8:$B$1087,A15,'9) Budget Baseline'!$H$8:$H$1087,">="&'14) Model Calc'!$B$9,'9) Budget Baseline'!$H$8:$H$1087,"<="&'14) Model Calc'!$B$10),IF('1) Budget-Actuals Dashboard'!$K$4="UKRI",SUMIFS('9) Budget Baseline'!$Q$8:$Q$1087,'9) Budget Baseline'!$B$8:$B$1087,A15,'9) Budget Baseline'!$H$8:$H$1087,">="&'14) Model Calc'!$B$9,'9) Budget Baseline'!$H$8:$H$1087,"<="&'14) Model Calc'!$B$10),SUMIFS('9) Budget Baseline'!$R$8:$R$1087,'9) Budget Baseline'!$B$8:$B$1087,A15,'9) Budget Baseline'!$H$8:$H$1087,">="&'14) Model Calc'!$B$9,'9) Budget Baseline'!$H$8:$H$1087,"<="&'14) Model Calc'!$B$10))) -> 416.66667 | I15: =IF('1) Budget-Actuals Dashboard'!$K$4="100% fEC",SUMIFS('6) Actuals Ledger - DI Costs'!$R$8:$R$2007,'6) Actuals Ledger - DI Costs'!$G$8:$G$2007,A15,'6) Actuals Ledger - DI Costs'!$C$8:$C$2007,">="&'14) Model Calc'!$B$9,'6) Actuals Ledger - DI Costs'!$C$8:$C$2007,"<="&'14) Model Calc'!$B$10)+SUMIFS('7) Allocations - DA Costs'!$O$8:$O$2007,'7) Allocations - DA Costs'!$D$8:$D$2007,A15,'7) Allocations - DA Costs'!$C$8:$C$2007,">="&'14) Model Calc'!$B$9,'7) Allocations - DA Costs'!$C$8:$C$2007,"<="&'14) Model Calc'!$B$10),IF('1) Budget-Actuals Dashboard'!$K$4="UKRI",SUMIFS('6) Actuals Ledger - DI Costs'!$S$8:$S$2007,'6) Actuals Ledger - DI Costs'!$G$8:$G$2007,A15,'6) Actuals Ledger - DI Costs'!$C$8:$C$2007,">="&'14) Model Calc'!$B$9,'6) Actuals Ledger - DI Costs'!$C$8:$C$2007,"<="&'14) Model Calc'!$B$10)+SUMIFS('7) Allocations - DA Costs'!$P$8:$P$2007,'7) Allocations - DA Costs'!$D$8:$D$2007,A15,'7) Allocations - DA Costs'!$C$8:$C$2007,">="&'14) Model Calc'!$B$9,'7) Allocations - DA Costs'!$C$8:$C$2007,"<="&'14) Model Calc'!$B$10),SUMIFS('6) Actuals Ledger - DI Costs'!$T$8:$T$2007,'6) Actuals Ledger - DI Costs'!$G$8:$G$2007,A15,'6) Actuals Ledger - DI Costs'!$C$8:$C$2007,">="&'14) Model Calc'!$B$9,'6) Actuals Ledger - DI Costs'!$C$8:$C$2007,"<="&'14) Model Calc'!$B$10)+SUMIFS('7) Allocations - DA Costs'!$Q$8:$Q$2007,'7) Allocations - DA Costs'!$D$8:$D$2007,A15,'7) Allocations - DA Costs'!$C$8:$C$2007,">="&'14) Model Calc'!$B$9,'7) Allocations - DA Costs'!$C$8:$C$2007,"<="&'14) Model Calc'!$B$10))) -> 575 | J15: =H15-I15 -> -158.33333 | K15: =IF(H15=0,"",J15/H15) -> -0.38 | L15: =IF('1) Budget-Actuals Dashboard'!$K$4="100% fEC",SUMIFS('8) Commitments Forecast'!$Q$8:$Q$507,'8) Commitments Forecast'!$H$8:$H$507,A15),IF('1) Budget-Actuals Dashboard'!$K$4="UKRI",SUMIFS('8) Commitments Forecast'!$R$8:$R$507,'8) Commitments Forecast'!$H$8:$H$507,A15),SUMIFS('8) Commitments Forecast'!$S$8:$S$507,'8) Commitments Forecast'!$H$8:$H$507,A15))) -> 450 | M15: =IFERROR(IF('1) Budget-Actuals Dashboard'!$K$4="100% fEC",INDEX('3) Forecast Bridge'!$L$8:$L$37,MATCH(A15,'3) Forecast Bridge'!$A$8:$A$37,0)),IF('1) Budget-Actuals Dashboard'!$K$4="UKRI",INDEX('3) Forecast Bridge'!$P$8:$P$37,MATCH(A15,'3) Forecast Bridge'!$A$8:$A$37,0)),INDEX('3) Forecast Bridge'!$Q$8:$Q$37,MATCH(A15,'3) Forecast Bridge'!$A$8:$A$37,0)))),0) -> 100
A16: WP1_IND | B16: RUSI - indirect allocation (dispensation proxy × eligible staff FTE) | C16: WP1 | D16: Indirect | E16: Indirect | F16: Indirect Costs | G16: =IF(AND(OR('1) Budget-Actuals Dashboard'!$C$5="All",C16='1) Budget-Actuals Dashboard'!$C$5),OR('1) Budget-Actuals Dashboard'!$G$5="All",D16='1) Budget-Actuals Dashboard'!$G$5),OR('1) Budget-Actuals Dashboard'!$K$5="All",E16='1) Budget-Actuals Dashboard'!$K$5)),"Yes","No") -> No | H16: =IF('1) Budget-Actuals Dashboard'!$K$4="100% fEC",SUMIFS('9) Budget Baseline'!$P$8:$P$1087,'9) Budget Baseline'!$B$8:$B$1087,A16,'9) Budget Baseline'!$H$8:$H$1087,">="&'14) Model Calc'!$B$9,'9) Budget Baseline'!$H$8:$H$1087,"<="&'14) Model Calc'!$B$10),IF('1) Budget-Actuals Dashboard'!$K$4="UKRI",SUMIFS('9) Budget Baseline'!$Q$8:$Q$1087,'9) Budget Baseline'!$B$8:$B$1087,A16,'9) Budget Baseline'!$H$8:$H$1087,">="&'14) Model Calc'!$B$9,'9) Budget Baseline'!$H$8:$H$1087,"<="&'14) Model Calc'!$B$10),SUMIFS('9) Budget Baseline'!$R$8:$R$1087,'9) Budget Baseline'!$B$8:$B$1087,A16,'9) Budget Baseline'!$H$8:$H$1087,">="&'14) Model Calc'!$B$9,'9) Budget Baseline'!$H$8:$H$1087,"<="&'14) Model Calc'!$B$10))) -> 5989.8958 | I16: =IF('1) Budget-Actuals Dashboard'!$K$4="100% fEC",SUMIFS('6) Actuals Ledger - DI Costs'!$R$8:$R$2007,'6) Actuals Ledger - DI Costs'!$G$8:$G$2007,A16,'6) Actuals Ledger - DI Costs'!$C$8:$C$2007,">="&'14) Model Calc'!$B$9,'6) Actuals Ledger - DI Costs'!$C$8:$C$2007,"<="&'14) Model Calc'!$B$10)+SUMIFS('7) Allocations - DA Costs'!$O$8:$O$2007,'7) Allocations - DA Costs'!$D$8:$D$2007,A16,'7) Allocations - DA Costs'!$C$8:$C$2007,">="&'14) Model Calc'!$B$9,'7) Allocations - DA Costs'!$C$8:$C$2007,"<="&'14) Model Calc'!$B$10),IF('1) Budget-Actuals Dashboard'!$K$4="UKRI",SUMIFS('6) Actuals Ledger - DI Costs'!$S$8:$S$2007,'6) Actuals Ledger - DI Costs'!$G$8:$G$2007,A16,'6) Actuals Ledger - DI Costs'!$C$8:$C$2007,">="&'14) Model Calc'!$B$9,'6) Actuals Ledger - DI Costs'!$C$8:$C$2007,"<="&'14) Model Calc'!$B$10)+SUMIFS('7) Allocations - DA Costs'!$P$8:$P$2007,'7) Allocations - DA Costs'!$D$8:$D$2007,A16,'7) Allocations - DA Costs'!$C$8:$C$2007,">="&'14) Model Calc'!$B$9,'7) Allocations - DA Costs'!$C$8:$C$2007,"<="&'14) Model Calc'!$B$10),SUMIFS('6) Actuals Ledger - DI Costs'!$T$8:$T$2007,'6) Actuals Ledger - DI Costs'!$G$8:$G$2007,A16,'6) Actuals Ledger - DI Costs'!$C$8:$C$2007,">="&'14) Model Calc'!$B$9,'6) Actuals Ledger - DI Costs'!$C$8:$C$2007,"<="&'14) Model Calc'!$B$10)+SUMIFS('7) Allocations - DA Costs'!$Q$8:$Q$2007,'7) Allocations - DA Costs'!$D$8:$D$2007,A16,'7) Allocations - DA Costs'!$C$8:$C$2007,">="&'14) Model Calc'!$B$9,'7) Allocations - DA Costs'!$C$8:$C$2007,"<="&'14) Model Calc'!$B$10))) -> 5953.96 | J16: =H16-I16 -> 35.935833 | K16: =IF(H16=0,"",J16/H16) -> 0.0059994087 | L16: =IF('1) Budget-Actuals Dashboard'!$K$4="100% fEC",SUMIFS('8) Commitments Forecast'!$Q$8:$Q$507,'8) Commitments Forecast'!$H$8:$H$507,A16),IF('1) Budget-Actuals Dashboard'!$K$4="UKRI",SUMIFS('8) Commitments Forecast'!$R$8:$R$507,'8) Commitments Forecast'!$H$8:$H$507,A16),SUMIFS('8) Commitments Forecast'!$S$8:$S$507,'8) Commitments Forecast'!$H$8:$H$507,A16))) -> 0 | M16: =IFERROR(IF('1) Budget-Actuals Dashboard'!$K$4="100% fEC",INDEX('3) Forecast Bridge'!$L$8:$L$37,MATCH(A16,'3) Forecast Bridge'!$A$8:$A$37,0)),IF('1) Budget-Actuals Dashboard'!$K$4="UKRI",INDEX('3) Forecast Bridge'!$P$8:$P$37,MATCH(A16,'3) Forecast Bridge'!$A$8:$A$37,0)),INDEX('3) Forecast Bridge'!$Q$8:$Q$37,MATCH(A16,'3) Forecast Bridge'!$A$8:$A$37,0)))),0) -> 0
A17: WP1_EST | B17: RUSI - non-laboratory estate allocation (dispensation proxy × eligible staff FTE) | C17: WP1 | D17: Directly Allocated | E17: Estates | F17: Estate Costs | G17: =IF(AND(OR('1) Budget-Actuals Dashboard'!$C$5="All",C17='1) Budget-Actuals Dashboard'!$C$5),OR('1) Budget-Actuals Dashboard'!$G$5="All",D17='1) Budget-Actuals Dashboard'!$G$5),OR('1) Budget-Actuals Dashboard'!$K$5="All",E17='1) Budget-Actuals Dashboard'!$K$5)),"Yes","No") -> No | H17: =IF('1) Budget-Actuals Dashboard'!$K$4="100% fEC",SUMIFS('9) Budget Baseline'!$P$8:$P$1087,'9) Budget Baseline'!$B$8:$B$1087,A17,'9) Budget Baseline'!$H$8:$H$1087,">="&'14) Model Calc'!$B$9,'9) Budget Baseline'!$H$8:$H$1087,"<="&'14) Model Calc'!$B$10),IF('1) Budget-Actuals Dashboard'!$K$4="UKRI",SUMIFS('9) Budget Baseline'!$Q$8:$Q$1087,'9) Budget Baseline'!$B$8:$B$1087,A17,'9) Budget Baseline'!$H$8:$H$1087,">="&'14) Model Calc'!$B$9,'9) Budget Baseline'!$H$8:$H$1087,"<="&'14) Model Calc'!$B$10),SUMIFS('9) Budget Baseline'!$R$8:$R$1087,'9) Budget Baseline'!$B$8:$B$1087,A17,'9) Budget Baseline'!$H$8:$H$1087,">="&'14) Model Calc'!$B$9,'9) Budget Baseline'!$H$8:$H$1087,"<="&'14) Model Calc'!$B$10))) -> 763.33333 | I17: =IF('1) Budget-Actuals Dashboard'!$K$4="100% fEC",SUMIFS('6) Actuals Ledger - DI Costs'!$R$8:$R$2007,'6) Actuals Ledger - DI Costs'!$G$8:$G$2007,A17,'6) Actuals Ledger - DI Costs'!$C$8:$C$2007,">="&'14) Model Calc'!$B$9,'6) Actuals Ledger - DI Costs'!$C$8:$C$2007,"<="&'14) Model Calc'!$B$10)+SUMIFS('7) Allocations - DA Costs'!$O$8:$O$2007,'7) Allocations - DA Costs'!$D$8:$D$2007,A17,'7) Allocations - DA Costs'!$C$8:$C$2007,">="&'14) Model Calc'!$B$9,'7) Allocations - DA Costs'!$C$8:$C$2007,"<="&'14) Model Calc'!$B$10),IF('1) Budget-Actuals Dashboard'!$K$4="UKRI",SUMIFS('6) Actuals Ledger - DI Costs'!$S$8:$S$2007,'6) Actuals Ledger - DI Costs'!$G$8:$G$2007,A17,'6) Actuals Ledger - DI Costs'!$C$8:$C$2007,">="&'14) Model Calc'!$B$9,'6) Actuals Ledger - DI Costs'!$C$8:$C$2007,"<="&'14) Model Calc'!$B$10)+SUMIFS('7) Allocations - DA Costs'!$P$8:$P$2007,'7) Allocations - DA Costs'!$D$8:$D$2007,A17,'7) Allocations - DA Costs'!$C$8:$C$2007,">="&'14) Model Calc'!$B$9,'7) Allocations - DA Costs'!$C$8:$C$2007,"<="&'14) Model Calc'!$B$10),SUMIFS('6) Actuals Ledger - DI Costs'!$T$8:$T$2007,'6) Actuals Ledger - DI Costs'!$G$8:$G$2007,A17,'6) Actuals Ledger - DI Costs'!$C$8:$C$2007,">="&'14) Model Calc'!$B$9,'6) Actuals Ledger - DI Costs'!$C$8:$C$2007,"<="&'14) Model Calc'!$B$10)+SUMIFS('7) Allocations - DA Costs'!$Q$8:$Q$2007,'7) Allocations - DA Costs'!$D$8:$D$2007,A17,'7) Allocations - DA Costs'!$C$8:$C$2007,">="&'14) Model Calc'!$B$9,'7) Allocations - DA Costs'!$C$8:$C$2007,"<="&'14) Model Calc'!$B$10))) -> 758.76 | J17: =H17-I17 -> 4.5733333 | K17: =IF(H17=0,"",J17/H17) -> 0.0059912664 | L17: =IF('1) Budget-Actuals Dashboard'!$K$4="100% fEC",SUMIFS('8) Commitments Forecast'!$Q$8:$Q$507,'8) Commitments Forecast'!$H$8:$H$507,A17),IF('1) Budget-Actuals Dashboard'!$K$4="UKRI",SUMIFS('8) Commitments Forecast'!$R$8:$R$507,'8) Commitments Forecast'!$H$8:$H$507,A17),SUMIFS('8) Commitments Forecast'!$S$8:$S$507,'8) Commitments Forecast'!$H$8:$H$507,A17))) -> 0 | M17: =IFERROR(IF('1) Budget-Actuals Dashboard'!$K$4="100% fEC",INDEX('3) Forecast Bridge'!$L$8:$L$37,MATCH(A17,'3) Forecast Bridge'!$A$8:$A$37,0)),IF('1) Budget-Actuals Dashboard'!$K$4="UKRI",INDEX('3) Forecast Bridge'!$P$8:$P$37,MATCH(A17,'3) Forecast Bridge'!$A$8:$A$37,0)),INDEX('3) Forecast Bridge'!$Q$8:$Q$37,MATCH(A17,'3) Forecast Bridge'!$A$8:$A$37,0)))),0) -> 0
A18: WP2_S01 | B18: RUSI - Project Officer (existing staff, DA) @GrB/4 | C18: WP2 | D18: Directly Allocated | E18: Staff | F18: Directly Allocated Staff | G18: =IF(AND(OR('1) Budget-Actuals Dashboard'!$C$5="All",C18='1) Budget-Actuals Dashboard'!$C$5),OR('1) Budget-Actuals Dashboard'!$G$5="All",D18='1) Budget-Actuals Dashboard'!$G$5),OR('1) Budget-Actuals Dashboard'!$K$5="All",E18='1) Budget-Actuals Dashboard'!$K$5)),"Yes","No") -> No | H18: =IF('1) Budget-Actuals Dashboard'!$K$4="100% fEC",SUMIFS('9) Budget Baseline'!$P$8:$P$1087,'9) Budget Baseline'!$B$8:$B$1087,A18,'9) Budget Baseline'!$H$8:$H$1087,">="&'14) Model Calc'!$B$9,'9) Budget Baseline'!$H$8:$H$1087,"<="&'14) Model Calc'!$B$10),IF('1) Budget-Actuals Dashboard'!$K$4="UKRI",SUMIFS('9) Budget Baseline'!$Q$8:$Q$1087,'9) Budget Baseline'!$B$8:$B$1087,A18,'9) Budget Baseline'!$H$8:$H$1087,">="&'14) Model Calc'!$B$9,'9) Budget Baseline'!$H$8:$H$1087,"<="&'14) Model Calc'!$B$10),SUMIFS('9) Budget Baseline'!$R$8:$R$1087,'9) Budget Baseline'!$B$8:$B$1087,A18,'9) Budget Baseline'!$H$8:$H$1087,">="&'14) Model Calc'!$B$9,'9) Budget Baseline'!$H$8:$H$1087,"<="&'14) Model Calc'!$B$10))) -> 490.625 | I18: =IF('1) Budget-Actuals Dashboard'!$K$4="100% fEC",SUMIFS('6) Actuals Ledger - DI Costs'!$R$8:$R$2007,'6) Actuals Ledger - DI Costs'!$G$8:$G$2007,A18,'6) Actuals Ledger - DI Costs'!$C$8:$C$2007,">="&'14) Model Calc'!$B$9,'6) Actuals Ledger - DI Costs'!$C$8:$C$2007,"<="&'14) Model Calc'!$B$10)+SUMIFS('7) Allocations - DA Costs'!$O$8:$O$2007,'7) Allocations - DA Costs'!$D$8:$D$2007,A18,'7) Allocations - DA Costs'!$C$8:$C$2007,">="&'14) Model Calc'!$B$9,'7) Allocations - DA Costs'!$C$8:$C$2007,"<="&'14) Model Calc'!$B$10),IF('1) Budget-Actuals Dashboard'!$K$4="UKRI",SUMIFS('6) Actuals Ledger - DI Costs'!$S$8:$S$2007,'6) Actuals Ledger - DI Costs'!$G$8:$G$2007,A18,'6) Actuals Ledger - DI Costs'!$C$8:$C$2007,">="&'14) Model Calc'!$B$9,'6) Actuals Ledger - DI Costs'!$C$8:$C$2007,"<="&'14) Model Calc'!$B$10)+SUMIFS('7) Allocations - DA Costs'!$P$8:$P$2007,'7) Allocations - DA Costs'!$D$8:$D$2007,A18,'7) Allocations - DA Costs'!$C$8:$C$2007,">="&'14) Model Calc'!$B$9,'7) Allocations - DA Costs'!$C$8:$C$2007,"<="&'14) Model Calc'!$B$10),SUMIFS('6) Actuals Ledger - DI Costs'!$T$8:$T$2007,'6) Actuals Ledger - DI Costs'!$G$8:$G$2007,A18,'6) Actuals Ledger - DI Costs'!$C$8:$C$2007,">="&'14) Model Calc'!$B$9,'6) Actuals Ledger - DI Costs'!$C$8:$C$2007,"<="&'14) Model Calc'!$B$10)+SUMIFS('7) Allocations - DA Costs'!$Q$8:$Q$2007,'7) Allocations - DA Costs'!$D$8:$D$2007,A18,'7) Allocations - DA Costs'!$C$8:$C$2007,">="&'14) Model Calc'!$B$9,'7) Allocations - DA Costs'!$C$8:$C$2007,"<="&'14) Model Calc'!$B$10))) -> 487.69 | J18: =H18-I18 -> 2.935 | K18: =IF(H18=0,"",J18/H18) -> 0.0059821656 | L18: =IF('1) Budget-Actuals Dashboard'!$K$4="100% fEC",SUMIFS('8) Commitments Forecast'!$Q$8:$Q$507,'8) Commitments Forecast'!$H$8:$H$507,A18),IF('1) Budget-Actuals Dashboard'!$K$4="UKRI",SUMIFS('8) Commitments Forecast'!$R$8:$R$507,'8) Commitments Forecast'!$H$8:$H$507,A18),SUMIFS('8) Commitments Forecast'!$S$8:$S$507,'8) Commitments Forecast'!$H$8:$H$507,A18))) -> 0 | M18: =IFERROR(IF('1) Budget-Actuals Dashboard'!$K$4="100% fEC",INDEX('3) Forecast Bridge'!$L$8:$L$37,MATCH(A18,'3) Forecast Bridge'!$A$8:$A$37,0)),IF('1) Budget-Actuals Dashboard'!$K$4="UKRI",INDEX('3) Forecast Bridge'!$P$8:$P$37,MATCH(A18,'3) Forecast Bridge'!$A$8:$A$37,0)),INDEX('3) Forecast Bridge'!$Q$8:$Q$37,MATCH(A18,'3) Forecast Bridge'!$A$8:$A$37,0)))),0) -> 0
A19: WP2_S02 | B19: RUSI - Research Analyst (existing staff, DA) @GrC/8 | C19: WP2 | D19: Directly Allocated | E19: Staff | F19: Directly Allocated Staff | G19: =IF(AND(OR('1) Budget-Actuals Dashboard'!$C$5="All",C19='1) Budget-Actuals Dashboard'!$C$5),OR('1) Budget-Actuals Dashboard'!$G$5="All",D19='1) Budget-Actuals Dashboard'!$G$5),OR('1) Budget-Actuals Dashboard'!$K$5="All",E19='1) Budget-Actuals Dashboard'!$K$5)),"Yes","No") -> No | H19: =IF('1) Budget-Actuals Dashboard'!$K$4="100% fEC",SUMIFS('9) Budget Baseline'!$P$8:$P$1087,'9) Budget Baseline'!$B$8:$B$1087,A19,'9) Budget Baseline'!$H$8:$H$1087,">="&'14) Model Calc'!$B$9,'9) Budget Baseline'!$H$8:$H$1087,"<="&'14) Model Calc'!$B$10),IF('1) Budget-Actuals Dashboard'!$K$4="UKRI",SUMIFS('9) Budget Baseline'!$Q$8:$Q$1087,'9) Budget Baseline'!$B$8:$B$1087,A19,'9) Budget Baseline'!$H$8:$H$1087,">="&'14) Model Calc'!$B$9,'9) Budget Baseline'!$H$8:$H$1087,"<="&'14) Model Calc'!$B$10),SUMIFS('9) Budget Baseline'!$R$8:$R$1087,'9) Budget Baseline'!$B$8:$B$1087,A19,'9) Budget Baseline'!$H$8:$H$1087,">="&'14) Model Calc'!$B$9,'9) Budget Baseline'!$H$8:$H$1087,"<="&'14) Model Calc'!$B$10))) -> 603.125 | I19: =IF('1) Budget-Actuals Dashboard'!$K$4="100% fEC",SUMIFS('6) Actuals Ledger - DI Costs'!$R$8:$R$2007,'6) Actuals Ledger - DI Costs'!$G$8:$G$2007,A19,'6) Actuals Ledger - DI Costs'!$C$8:$C$2007,">="&'14) Model Calc'!$B$9,'6) Actuals Ledger - DI Costs'!$C$8:$C$2007,"<="&'14) Model Calc'!$B$10)+SUMIFS('7) Allocations - DA Costs'!$O$8:$O$2007,'7) Allocations - DA Costs'!$D$8:$D$2007,A19,'7) Allocations - DA Costs'!$C$8:$C$2007,">="&'14) Model Calc'!$B$9,'7) Allocations - DA Costs'!$C$8:$C$2007,"<="&'14) Model Calc'!$B$10),IF('1) Budget-Actuals Dashboard'!$K$4="UKRI",SUMIFS('6) Actuals Ledger - DI Costs'!$S$8:$S$2007,'6) Actuals Ledger - DI Costs'!$G$8:$G$2007,A19,'6) Actuals Ledger - DI Costs'!$C$8:$C$2007,">="&'14) Model Calc'!$B$9,'6) Actuals Ledger - DI Costs'!$C$8:$C$2007,"<="&'14) Model Calc'!$B$10)+SUMIFS('7) Allocations - DA Costs'!$P$8:$P$2007,'7) Allocations - DA Costs'!$D$8:$D$2007,A19,'7) Allocations - DA Costs'!$C$8:$C$2007,">="&'14) Model Calc'!$B$9,'7) Allocations - DA Costs'!$C$8:$C$2007,"<="&'14) Model Calc'!$B$10),SUMIFS('6) Actuals Ledger - DI Costs'!$T$8:$T$2007,'6) Actuals Ledger - DI Costs'!$G$8:$G$2007,A19,'6) Actuals Ledger - DI Costs'!$C$8:$C$2007,">="&'14) Model Calc'!$B$9,'6) Actuals Ledger - DI Costs'!$C$8:$C$2007,"<="&'14) Model Calc'!$B$10)+SUMIFS('7) Allocations - DA Costs'!$Q$8:$Q$2007,'7) Allocations - DA Costs'!$D$8:$D$2007,A19,'7) Allocations - DA Costs'!$C$8:$C$2007,">="&'14) Model Calc'!$B$9,'7) Allocations - DA Costs'!$C$8:$C$2007,"<="&'14) Model Calc'!$B$10))) -> 599.52 | J19: =H19-I19 -> 3.605 | K19: =IF(H19=0,"",J19/H19) -> 0.0059772021 | L19: =IF('1) Budget-Actuals Dashboard'!$K$4="100% fEC",SUMIFS('8) Commitments Forecast'!$Q$8:$Q$507,'8) Commitments Forecast'!$H$8:$H$507,A19),IF('1) Budget-Actuals Dashboard'!$K$4="UKRI",SUMIFS('8) Commitments Forecast'!$R$8:$R$507,'8) Commitments Forecast'!$H$8:$H$507,A19),SUMIFS('8) Commitments Forecast'!$S$8:$S$507,'8) Commitments Forecast'!$H$8:$H$507,A19))) -> 0 | M19: =IFERROR(IF('1) Budget-Actuals Dashboard'!$K$4="100% fEC",INDEX('3) Forecast Bridge'!$L$8:$L$37,MATCH(A19,'3) Forecast Bridge'!$A$8:$A$37,0)),IF('1) Budget-Actuals Dashboard'!$K$4="UKRI",INDEX('3) Forecast Bridge'!$P$8:$P$37,MATCH(A19,'3) Forecast Bridge'!$A$8:$A$37,0)),INDEX('3) Forecast Bridge'!$Q$8:$Q$37,MATCH(A19,'3) Forecast Bridge'!$A$8:$A$37,0)))),0) -> 0
... A37: WP3_EST | B37: RUSI - non-laboratory estate allocation (dispensation proxy × eligible staff FTE) | C37: WP3 | D37: Directly Allocated | E37: Estates | F37: Estate Costs | G37: =IF(AND(OR('1) Budget-Actuals Dashboard'!$C$5="All",C37='1) Budget-Actuals Dashboard'!$C$5),OR('1) Budget-Actuals Dashboard'!$G$5="All",D37='1) Budget-Actuals Dashboard'!$G$5),OR('1) Budget-Actuals Dashboard'!$K$5="All",E37='1) Budget-Actuals Dashboard'!$K$5)),"Yes","No") -> No | H37: =IF('1) Budget-Actuals Dashboard'!$K$4="100% fEC",SUMIFS('9) Budget Baseline'!$P$8:$P$1087,'9) Budget Baseline'!$B$8:$B$1087,A37,'9) Budget Baseline'!$H$8:$H$1087,">="&'14) Model Calc'!$B$9,'9) Budget Baseline'!$H$8:$H$1087,"<="&'14) Model Calc'!$B$10),IF('1) Budget-Actuals Dashboard'!$K$4="UKRI",SUMIFS('9) Budget Baseline'!$Q$8:$Q$1087,'9) Budget Baseline'!$B$8:$B$1087,A37,'9) Budget Baseline'!$H$8:$H$1087,">="&'14) Model Calc'!$B$9,'9) Budget Baseline'!$H$8:$H$1087,"<="&'14) Model Calc'!$B$10),SUMIFS('9) Budget Baseline'!$R$8:$R$1087,'9) Budget Baseline'!$B$8:$B$1087,A37,'9) Budget Baseline'!$H$8:$H$1087,">="&'14) Model Calc'!$B$9,'9) Budget Baseline'!$H$8:$H$1087,"<="&'14) Model Calc'!$B$10))) -> 396.93333 | I37: =IF('1) Budget-Actuals Dashboard'!$K$4="100% fEC",SUMIFS('6) Actuals Ledger - DI Costs'!$R$8:$R$2007,'6) Actuals Ledger - DI Costs'!$G$8:$G$2007,A37,'6) Actuals Ledger - DI Costs'!$C$8:$C$2007,">="&'14) Model Calc'!$B$9,'6) Actuals Ledger - DI Costs'!$C$8:$C$2007,"<="&'14) Model Calc'!$B$10)+SUMIFS('7) Allocations - DA Costs'!$O$8:$O$2007,'7) Allocations - DA Costs'!$D$8:$D$2007,A37,'7) Allocations - DA Costs'!$C$8:$C$2007,">="&'14) Model Calc'!$B$9,'7) Allocations - DA Costs'!$C$8:$C$2007,"<="&'14) Model Calc'!$B$10),IF('1) Budget-Actuals Dashboard'!$K$4="UKRI",SUMIFS('6) Actuals Ledger - DI Costs'!$S$8:$S$2007,'6) Actuals Ledger - DI Costs'!$G$8:$G$2007,A37,'6) Actuals Ledger - DI Costs'!$C$8:$C$2007,">="&'14) Model Calc'!$B$9,'6) Actuals Ledger - DI Costs'!$C$8:$C$2007,"<="&'14) Model Calc'!$B$10)+SUMIFS('7) Allocations - DA Costs'!$P$8:$P$2007,'7) Allocations - DA Costs'!$D$8:$D$2007,A37,'7) Allocations - DA Costs'!$C$8:$C$2007,">="&'14) Model Calc'!$B$9,'7) Allocations - DA Costs'!$C$8:$C$2007,"<="&'14) Model Calc'!$B$10),SUMIFS('6) Actuals Ledger - DI Costs'!$T$8:$T$2007,'6) Actuals Ledger - DI Costs'!$G$8:$G$2007,A37,'6) Actuals Ledger - DI Costs'!$C$8:$C$2007,">="&'14) Model Calc'!$B$9,'6) Actuals Ledger - DI Costs'!$C$8:$C$2007,"<="&'14) Model Calc'!$B$10)+SUMIFS('7) Allocations - DA Costs'!$Q$8:$Q$2007,'7) Allocations - DA Costs'!$D$8:$D$2007,A37,'7) Allocations - DA Costs'!$C$8:$C$2007,">="&'14) Model Calc'!$B$9,'7) Allocations - DA Costs'!$C$8:$C$2007,"<="&'14) Model Calc'!$B$10))) -> 394.56 | J37: =H37-I37 -> 2.3733333 | K37: =IF(H37=0,"",J37/H37) -> 0.0059791737 | L37: =IF('1) Budget-Actuals Dashboard'!$K$4="100% fEC",SUMIFS('8) Commitments Forecast'!$Q$8:$Q$507,'8) Commitments Forecast'!$H$8:$H$507,A37),IF('1) Budget-Actuals Dashboard'!$K$4="UKRI",SUMIFS('8) Commitments Forecast'!$R$8:$R$507,'8) Commitments Forecast'!$H$8:$H$507,A37),SUMIFS('8) Commitments Forecast'!$S$8:$S$507,'8) Commitments Forecast'!$H$8:$H$507,A37))) -> 0 | M37: =IFERROR(IF('1) Budget-Actuals Dashboard'!$K$4="100% fEC",INDEX('3) Forecast Bridge'!$L$8:$L$37,MATCH(A37,'3) Forecast Bridge'!$A$8:$A$37,0)),IF('1) Budget-Actuals Dashboard'!$K$4="UKRI",INDEX('3) Forecast Bridge'!$P$8:$P$37,MATCH(A37,'3) Forecast Bridge'!$A$8:$A$37,0)),INDEX('3) Forecast Bridge'!$Q$8:$Q$37,MATCH(A37,'3) Forecast Bridge'!$A$8:$A$37,0)))),0) -> 0
A40: Interpretation: positive variance is remaining headroom and negative variance is overspend/exposure. Neither is automatically favourable or unfavourable: timing, delivery progress, eligibility and evidence must be reviewed together.

Sheet 3) Forecast Bridge
A1: Item-level Forecast at Completion bridge
A2: Budget breakdown by each line item and current spend against. Confirmed (Realised costs) + Committed (costs liable to pay but unrealised) + Unspent (unrealised costs) = 100% fCE* *At the time of the Dashboard cut-off and based on costs being verified against the project
A4: Forecast at Completion should never overwrites the approved Budget. Only us the blue Forecast Adjustment column as an input (use it to record an expected committment, anticipated risk or saving etc.) and review monthly. Everything else is forecasted from the baseline budget, confirmedf cost ledgers and the commitment register.
A7: Budget Item ID | B7: Description | C7: Work Package | D7: fEC Heading | E7: fEC Subheading | F7: Approved Budget | G7: Spend to Date | H7: Open Commitments | I7: Forecast Adjustment | J7: Uncommitted ETC | K7: Forecast at Completion | L7: Variance to Budget | M7: Funding Rate | N7: FAC UKRI | O7: FAC RUSI | P7: Variance UKRI | Q7: Variance RUSI | R7: Notes
A8: WP1_S01 | B8: RUSI - Project Officer (existing staff, DA) @GrB/4 | C8: WP1 | D8: Directly Allocated | E8: Staff | F8: =SUMIFS('9) Budget Baseline'!$P$8:$P$1087,'9) Budget Baseline'!$B$8:$B$1087,A8) -> 14915 | G8: =SUMIFS('6) Actuals Ledger - DI Costs'!$R$8:$R$2007,'6) Actuals Ledger - DI Costs'!$G$8:$G$2007,A8,'6) Actuals Ledger - DI Costs'!$C$8:$C$2007,"<="&'1) Budget-Actuals Dashboard'!$C$4)+SUMIFS('7) Allocations - DA Costs'!$O$8:$O$2007,'7) Allocations - DA Costs'!$D$8:$D$2007,A8,'7) Allocations - DA Costs'!$C$8:$C$2007,"<="&'1) Budget-Actuals Dashboard'!$C$4) -> 1625.59 | H8: =SUMIFS('8) Commitments Forecast'!$Q$8:$Q$507,'8) Commitments Forecast'!$H$8:$H$507,A8) -> 0 | I8: 0 | J8: =MAX(0,F8+I8-G8-H8) -> 13289.41 | K8: =G8+H8+J8 -> 14915 | L8: =F8-K8 -> 0 | M8: =IFERROR(INDEX('12) Budget Line Mapping'!$G$8:$G$37,MATCH(A8,'12) Budget Line Mapping'!$A$8:$A$37,0)),0) -> 0.8 | N8: =K8*M8 -> 11932 | O8: =K8-N8 -> 2983 | P8: =L8*M8 -> 0 | Q8: =L8-P8 -> 0 | R8: Base ETC follows remaining approved Budget.
