Workbook
Name band_tbl: Rates!#REF!
Name buffer_major: 'Trip plan'!$B$6
Name buffer_other: 'Trip plan'!$B$7
Name fare_escal: 'Trip plan'!$B$8
Name fx_budget: FX!$G$7:$G$118
Name fx_ccy: FX!$A$7:$A$118
Name loc_list: Rates!$A$5:$A$289
Name loc_list_UK: Additional_Val!$B$4:$B$291
Name month_list: Table2[Month List]
Name rate_date: 'Trip plan'!$B$5
Name rates_tbl: Rates!$A$5:$Q$289
Name season_tbl: Rates!#REF!

Sheet Trip plan
A1: Overseas Trip cost estimator
A2: Multi-strand costing tool, particularly useful for UK-based research institutions. Instant day rate, accommodation and other estimates provided directly from the latest HMRC published overseas scale rates. As flight data and APIs are heavily guarded from public access, there are 2 approaches for costing air fares: 1) Input your own quote from your comparison site of choice (SkySkanner, Expedia etc.); or 2) Use the integrated Google Flights search shortcut to grab a quote that way.
A4: Assumptions | L4: Schedule totals
A5: Rate date | B5: 46260 | C5: The day the exchange rates are taken from. Change it and the whole schedule re-prices. Must be a day the market was open. | L5: Accommodation | M5: Subsistence | N5: Airfare | O5: Other | P5: TOTAL
A6: FX buffer - EUR and USD | B6: 0 | C6: Zero by default: UK research offices use a corporate rate for these. Substitute your own if you have one. | L6: =SUMIFS(O$16:O$40,$U$16:$U$40,">=0") -> 3040.6118 | M6: =SUMIFS(P$16:P$40,$U$16:$U$40,">=0") -> 1185.2129 | N6: =SUMIFS(S$16:S$40,$U$16:$U$40,">=0") -> 3111 | O6: =SUMIFS(T$16:T$40,$U$16:$U$40,">=0") -> 360 | P6: =SUM(L6:O6) -> 7696.8247
A7: FX buffer - all others | B7: 0.1 | C7: Ten per cent (standard UCL research policy for costing). Consider higher for a volatile currency.
A8: Fare escalation | B8: 1 | C8: Multiplier on the band placeholder fares. 1.00 leaves them as published.
A9: Workbook prepared | B9: 1 September 2026 | C9: Rate data captured 26 August 2026. See the Notes sheet for sources.
A11: =IF(N($P$6)<=0,"Pick a destination and a month, then type the number of travellers and nights. Everything else is looked up or calculated.","Of the £"&TEXT($P$6,"#,##0")&" total, "&TEXT(($L$6+$M$6)/$P$6,"0%")&" is backed by a published HMRC rate (accommodation and subsistence) and "&TEXT(($N$6+$O$6)/$P$6,"0%")&" is estimate or user input (airfare and other).") -> Of the £7,697 total, 55% is backed by a published HMRC rate (accommodation and subsistence) and 45% is estimate or user input (airfare and other).
A12: =IF(SUMPRODUCT(($C$16:$C$40<>"")*1)=0,"",IF(SUMPRODUCT(($C$16:$C$40<>"")*($U$16:$U$40=""))=0,"All "&SUMPRODUCT(($C$16:$C$40<>"")*1)&" trip(s) entered are fully costed.",SUMPRODUCT(($C$16:$C$40<>"")*($U$16:$U$40=""))&" of "&SUMPRODUCT(($C$16:$C$40<>"")*1)&" trip(s) entered could not be costed. The total above excludes them. The Check column says what each one needs.")) -> All 3 trip(s) entered are fully costed.
A13: Type in the shaded cells (blue figures). Green cells are looked up from Rates and FX. Black cells are calculated. A blank money cell is never a zero - it means the row is not costable yet.
O14: Backed by a published rate | T14: Estimate
A15: Trip Name | B15: Departure Location (or Closest) [Defaults to London, UK] | C15: Destination Location (or Closest Available) | D15: Date of Departure | E15: Month | F15: Travellers | G15: Nights | H15: Final day, no overnight | I15: Approx Date of Return | J15: Quoted fare £ per traveller | K15: Other £ per traveller | L15: Band | M15: Meals ccy | N15: Room ccy | O15: Accommodation £ | P15: Subsistence £ | Q15: Find Cheapest Airfare | R15: Airfaire Quick Search | S15: Airfare £ | T15: Other £ | U15: Trip total £ | V15: Check Column
A16: Partner workshop | C16: Jakarta, Indonesia | D16: 46305 | E16: =IF(D16<>"",_xlfn.XLOOKUP(MONTH(D16),Table2[Month Number],month_list,"",0,1),"") -> Oct | F16: 2 | G16: 4 | H16: None | I16: =IF(D16<>0,SUM(D16,G16),"") -> 46309 | J16: 664 | K16: 120 | L16: =IF($C16="","",IFERROR(INDEX(rates_tbl,MATCH($C16,loc_list,0),3),"")) -> 5 | M16: =IF($C16="","",IFERROR(INDEX(rates_tbl,MATCH($C16,loc_list,0),4),"")) -> IDR | N16: =IF($C16="","",IFERROR(INDEX(rates_tbl,MATCH($C16,loc_list,0),5),"")) -> USD | O16: =IF(NOT(AND($C16<>"",ISNUMBER(MATCH($C16,loc_list,0)),ISNUMBER($F16),$F16>0,OR(N($G16)>0,$H16<>""))),"",IF(N($G16)<=0,0,IF(NOT(ISNUMBER(IFERROR(INDEX(fx_budget,MATCH($N16,fx_ccy,0)),""))),"",N($G16)*INDEX(rates_tbl,MATCH($C16,loc_list,0),10)*$F16/IFERROR(INDEX(fx_budget,MATCH($N16,fx_ccy,0)),"")))) -> 909.75789 | P16: =IF(NOT(AND($C16<>"",ISNUMBER(MATCH($C16,loc_list,0)),ISNUMBER($F16),$F16>0,OR(N($G16)>0,$H16<>""))),"",IF(NOT(ISNUMBER(IFERROR(INDEX(fx_budget,MATCH($M16,fx_ccy,0)),""))),"",(N($G16)*INDEX(rates_tbl,MATCH($C16,loc_list,0),9)+IF($H16="Over 10 hours",INDEX(rates_tbl,MATCH($C16,loc_list,0),8),IF($H16="Over 5 hours",INDEX(rates_tbl,MATCH($C16,loc_list,0),7),0)))*$F16/IFERROR(INDEX(fx_budget,MATCH($M16,fx_ccy,0)),""))) -> 359.70829 | Q16: =IF(LEN(R16)-LEN(SUBSTITUTE(R16,"+",""))>=4, HYPERLINK(R16, _xlfn.TEXTJOIN(" ",TRUE,"Click for Google Flights Prices for",IF(B16="","London",IFERROR(_xlfn.TEXTBEFORE(B16,", "),B16)),"to",IFERROR(_xlfn.TEXTBEFORE(C16,", "),C16))), "") -> Click for Google Flights Prices for London to Jakarta | R16: =HYPERLINK((IF(OR(C16="",D16="",I16=""),"","https://www.google.com/search?q=flights+from+"&SUBSTITUTE(IF(B16="","London, UK",B16)," ","+")&"+to+"&SUBSTITUTE(C16," ","+")&"+"&TEXT(D16,"d+mmmm+yyyy")&"+to+"&TEXT(I16,"d+mmmm+yyyy")))) -> https://www.google.com/search?q=flights+from+London,+UK+to+Jakarta,+Indonesia+10+October+2026+to+14+October+2026 | S16: =IF(J16<>0,PRODUCT(J16,F16),"") -> 1328 | T16: =IF(NOT(AND($C16<>"",ISNUMBER(MATCH($C16,loc_list,0)),ISNUMBER($F16),$F16>0,OR(N($G16)>0,$H16<>""))),"",N($K16)*$F16) -> 240 | U16: =IF(NOT(AND($C16<>"",ISNUMBER(MATCH($C16,loc_list,0)),ISNUMBER($F16),$F16>0,OR(N($G16)>0,$H16<>""))),"",IF(COUNT($O16:$T16)<4,"",SUM($O16:$T16))) -> 2837.4662 | V16: =IF($C16="","",IF(NOT(ISNUMBER(MATCH($C16,loc_list,0))),"Destination not recognised. Choose one from the dropdown.",IF(NOT(ISNUMBER($F16)),"Enter the number of travellers.",IF($F16<=0,"Travellers must be 1 or more.",IF(AND(N($G16)<=0,$H16=""),"Enter the number of nights. For a day of travel with no overnight, set the final-day column — choose None if no subsistence is claimed.",IF(NOT(ISNUMBER(IFERROR(INDEX(fx_budget,MATCH($M16,fx_ccy,0)),""))),"No exchange rate for "&$M16&IF($M16=$N16,""," (the meals currency)")&". Add one on the FX sheet.",IF(AND(N($N16)>0,NOT(ISNUMBER(IFERROR(INDEX(fx_budget,MATCH($N16,fx_ccy,0)),"")))),"No exchange rate for "&$N16&" (the room-rate currency). Add one on the FX sheet.",IF(NOT(ISNUMBER($G16)),"Enter a quoted fare or search for one using the Google Flights link!",IF($M16<>$N16,"Dual currency: meals in "&$M16&", room rate in "&$N16&". Converted separately.",""))))))))) -> Dual currency: meals in IDR, room rate in USD. Converted separately.
A17: SHOC 2.0 Travel | B17: London, UK | C17: Bogota, Colombia | D17: 46309 | E17: =IF(D17<>"",_xlfn.XLOOKUP(MONTH(D17),Table2[Month Number],month_list,"",0,1),"") -> Oct | F17: 2 | G17: 6 | I17: =IF(D17<>0,SUM(D17,G17),"") -> 46315 | J17: 674 | L17: =IF($C17="","",IFERROR(INDEX(rates_tbl,MATCH($C17,loc_list,0),3),"")) -> 4 | M17: =IF($C17="","",IFERROR(INDEX(rates_tbl,MATCH($C17,loc_list,0),4),"")) -> COP | N17: =IF($C17="","",IFERROR(INDEX(rates_tbl,MATCH($C17,loc_list,0),5),"")) -> COP | O17: =IF(NOT(AND($C17<>"",ISNUMBER(MATCH($C17,loc_list,0)),ISNUMBER($F17),$F17>0,OR(N($G17)>0,$H17<>""))),"",IF(N($G17)<=0,0,IF(NOT(ISNUMBER(IFERROR(INDEX(fx_budget,MATCH($N17,fx_ccy,0)),""))),"",N($G17)*INDEX(rates_tbl,MATCH($C17,loc_list,0),10)*$F17/IFERROR(INDEX(fx_budget,MATCH($N17,fx_ccy,0)),"")))) -> 1280.6827 | P17: =IF(NOT(AND($C17<>"",ISNUMBER(MATCH($C17,loc_list,0)),ISNUMBER($F17),$F17>0,OR(N($G17)>0,$H17<>""))),"",IF(NOT(ISNUMBER(IFERROR(INDEX(fx_budget,MATCH($M17,fx_ccy,0)),""))),"",(N($G17)*INDEX(rates_tbl,MATCH($C17,loc_list,0),9)+IF($H17="Over 10 hours",INDEX(rates_tbl,MATCH($C17,loc_list,0),8),IF($H17="Over 5 hours",INDEX(rates_tbl,MATCH($C17,loc_list,0),7),0)))*$F17/IFERROR(INDEX(fx_budget,MATCH($M17,fx_ccy,0)),""))) -> 435.09362 | Q17: =IF(LEN(R17)-LEN(SUBSTITUTE(R17,"+",""))>=4, HYPERLINK(R17, _xlfn.TEXTJOIN(" ",TRUE,"Click for Google Flights Prices for",IF(B17="","London",IFERROR(_xlfn.TEXTBEFORE(B17,", "),B17)),"to",IFERROR(_xlfn.TEXTBEFORE(C17,", "),C17))), "") -> Click for Google Flights Prices for London to Bogota | R17: =HYPERLINK((IF(OR(C17="",D17="",I17=""),"","https://www.google.com/search?q=flights+from+"&SUBSTITUTE(IF(B17="","London, UK",B17)," ","+")&"+to+"&SUBSTITUTE(C17," ","+")&"+"&TEXT(D17,"d+mmmm+yyyy")&"+to+"&TEXT(I17,"d+mmmm+yyyy")))) -> https://www.google.com/search?q=flights+from+London,+UK+to+Bogota,+Colombia+14+October+2026+to+20+October+2026 | S17: =IF(J17<>0,PRODUCT(J17,F17),"") -> 1348 | T17: =IF(NOT(AND($C17<>"",ISNUMBER(MATCH($C17,loc_list,0)),ISNUMBER($F17),$F17>0,OR(N($G17)>0,$H17<>""))),"",N($K17)*$F17) -> 0 | U17: =IF(NOT(AND($C17<>"",ISNUMBER(MATCH($C17,loc_list,0)),ISNUMBER($F17),$F17>0,OR(N($G17)>0,$H17<>""))),"",IF(COUNT($O17:$T17)<4,"",SUM($O17:$T17))) -> 3063.7763 | V17: =IF($C17="","",IF(NOT(ISNUMBER(MATCH($C17,loc_list,0))),"Destination not recognised. Choose one from the dropdown.",IF(NOT(ISNUMBER($F17)),"Enter the number of travellers.",IF($F17<=0,"Travellers must be 1 or more.",IF(AND(N($G17)<=0,$H17=""),"Enter the number of nights. For a day of travel with no overnight, set the final-day column — choose None if no subsistence is claimed.",IF(NOT(ISNUMBER(IFERROR(INDEX(fx_budget,MATCH($M17,fx_ccy,0)),""))),"No exchange rate for "&$M17&IF($M17=$N17,""," (the meals currency)")&". Add one on the FX sheet.",IF(AND(N($N17)>0,NOT(ISNUMBER(IFERROR(INDEX(fx_budget,MATCH($N17,fx_ccy,0)),"")))),"No exchange rate for "&$N17&" (the room-rate currency). Add one on the FX sheet.",IF(NOT(ISNUMBER($G17)),"Enter a quoted fare or search for one using the Google Flights link!",IF($M17<>$N17,"Dual currency: meals in "&$M17&", room rate in "&$N17&". Converted separately.","")))))))))
A18: Donor conference | C18: Brussels, Belgium | D18: 45843 | E18: =IF(D18<>"",_xlfn.XLOOKUP(MONTH(D18),Table2[Month Number],month_list,"",0,1),"") -> Jul | F18: 3 | G18: 2 | H18: None | I18: =IF(D18<>0,SUM(D18,G18),"") -> 45845 | J18: 145 | K18: 40 | L18: =IF($C18="","",IFERROR(INDEX(rates_tbl,MATCH($C18,loc_list,0),3),"")) -> 1 | M18: =IF($C18="","",IFERROR(INDEX(rates_tbl,MATCH($C18,loc_list,0),4),"")) -> EUR | N18: =IF($C18="","",IFERROR(INDEX(rates_tbl,MATCH($C18,loc_list,0),5),"")) -> EUR | O18: =IF(NOT(AND($C18<>"",ISNUMBER(MATCH($C18,loc_list,0)),ISNUMBER($F18),$F18>0,OR(N($G18)>0,$H18<>""))),"",IF(N($G18)<=0,0,IF(NOT(ISNUMBER(IFERROR(INDEX(fx_budget,MATCH($N18,fx_ccy,0)),""))),"",N($G18)*INDEX(rates_tbl,MATCH($C18,loc_list,0),10)*$F18/IFERROR(INDEX(fx_budget,MATCH($N18,fx_ccy,0)),"")))) -> 850.17123 | P18: =IF(NOT(AND($C18<>"",ISNUMBER(MATCH($C18,loc_list,0)),ISNUMBER($F18),$F18>0,OR(N($G18)>0,$H18<>""))),"",IF(NOT(ISNUMBER(IFERROR(INDEX(fx_budget,MATCH($M18,fx_ccy,0)),""))),"",(N($G18)*INDEX(rates_tbl,MATCH($C18,loc_list,0),9)+IF($H18="Over 10 hours",INDEX(rates_tbl,MATCH($C18,loc_list,0),8),IF($H18="Over 5 hours",INDEX(rates_tbl,MATCH($C18,loc_list,0),7),0)))*$F18/IFERROR(INDEX(fx_budget,MATCH($M18,fx_ccy,0)),""))) -> 390.41096 | Q18: =IF(LEN(R18)-LEN(SUBSTITUTE(R18,"+",""))>=4, HYPERLINK(R18, _xlfn.TEXTJOIN(" ",TRUE,"Click for Google Flights Prices for",IF(B18="","London",IFERROR(_xlfn.TEXTBEFORE(B18,", "),B18)),"to",IFERROR(_xlfn.TEXTBEFORE(C18,", "),C18))), "") -> Click for Google Flights Prices for London to Brussels | R18: =HYPERLINK((IF(OR(C18="",D18="",I18=""),"","https://www.google.com/search?q=flights+from+"&SUBSTITUTE(IF(B18="","London, UK",B18)," ","+")&"+to+"&SUBSTITUTE(C18," ","+")&"+"&TEXT(D18,"d+mmmm+yyyy")&"+to+"&TEXT(I18,"d+mmmm+yyyy")))) -> https://www.google.com/search?q=flights+from+London,+UK+to+Brussels,+Belgium+5+July+2025+to+7+July+2025 | S18: =IF(J18<>0,PRODUCT(J18,F18),"") -> 435 | T18: =IF(NOT(AND($C18<>"",ISNUMBER(MATCH($C18,loc_list,0)),ISNUMBER($F18),$F18>0,OR(N($G18)>0,$H18<>""))),"",N($K18)*$F18) -> 120 | U18: =IF(NOT(AND($C18<>"",ISNUMBER(MATCH($C18,loc_list,0)),ISNUMBER($F18),$F18>0,OR(N($G18)>0,$H18<>""))),"",IF(COUNT($O18:$T18)<4,"",SUM($O18:$T18))) -> 1795.5822 | V18: =IF($C18="","",IF(NOT(ISNUMBER(MATCH($C18,loc_list,0))),"Destination not recognised. Choose one from the dropdown.",IF(NOT(ISNUMBER($F18)),"Enter the number of travellers.",IF($F18<=0,"Travellers must be 1 or more.",IF(AND(N($G18)<=0,$H18=""),"Enter the number of nights. For a day of travel with no overnight, set the final-day column — choose None if no subsistence is claimed.",IF(NOT(ISNUMBER(IFERROR(INDEX(fx_budget,MATCH($M18,fx_ccy,0)),""))),"No exchange rate for "&$M18&IF($M18=$N18,""," (the meals currency)")&". Add one on the FX sheet.",IF(AND(N($N18)>0,NOT(ISNUMBER(IFERROR(INDEX(fx_budget,MATCH($N18,fx_ccy,0)),"")))),"No exchange rate for "&$N18&" (the room-rate currency). Add one on the FX sheet.",IF(NOT(ISNUMBER($G18)),"Enter a quoted fare or search for one using the Google Flights link!",IF($M18<>$N18,"Dual currency: meals in "&$M18&", room rate in "&$N18&". Converted separately.","")))))))))
E19: =IF(D19<>"",_xlfn.XLOOKUP(MONTH(D19),Table2[Month Number],month_list,"",0,1),"") | I19: =IF(D19<>0,SUM(D19,G19),"") | L19: =IF($C19="","",IFERROR(INDEX(rates_tbl,MATCH($C19,loc_list,0),3),"")) | M19: =IF($C19="","",IFERROR(INDEX(rates_tbl,MATCH($C19,loc_list,0),4),"")) | N19: =IF($C19="","",IFERROR(INDEX(rates_tbl,MATCH($C19,loc_list,0),5),"")) | O19: =IF(NOT(AND($C19<>"",ISNUMBER(MATCH($C19,loc_list,0)),ISNUMBER($F19),$F19>0,OR(N($G19)>0,$H19<>""))),"",IF(N($G19)<=0,0,IF(NOT(ISNUMBER(IFERROR(INDEX(fx_budget,MATCH($N19,fx_ccy,0)),""))),"",N($G19)*INDEX(rates_tbl,MATCH($C19,loc_list,0),10)*$F19/IFERROR(INDEX(fx_budget,MATCH($N19,fx_ccy,0)),"")))) | P19: =IF(NOT(AND($C19<>"",ISNUMBER(MATCH($C19,loc_list,0)),ISNUMBER($F19),$F19>0,OR(N($G19)>0,$H19<>""))),"",IF(NOT(ISNUMBER(IFERROR(INDEX(fx_budget,MATCH($M19,fx_ccy,0)),""))),"",(N($G19)*INDEX(rates_tbl,MATCH($C19,loc_list,0),9)+IF($H19="Over 10 hours",INDEX(rates_tbl,MATCH($C19,loc_list,0),8),IF($H19="Over 5 hours",INDEX(rates_tbl,MATCH($C19,loc_list,0),7),0)))*$F19/IFERROR(INDEX(fx_budget,MATCH($M19,fx_ccy,0)),""))) | Q19: =IF(LEN(R19)-LEN(SUBSTITUTE(R19,"+",""))>=4, HYPERLINK(R19, _xlfn.TEXTJOIN(" ",TRUE,"Click for Google Flights Prices for",IF(B19="","London",IFERROR(_xlfn.TEXTBEFORE(B19,", "),B19)),"to",IFERROR(_xlfn.TEXTBEFORE(C19,", "),C19))), "") | R19: =HYPERLINK((IF(OR(C19="",D19="",I19=""),"","https://www.google.com/search?q=flights+from+"&SUBSTITUTE(IF(B19="","London, UK",B19)," ","+")&"+to+"&SUBSTITUTE(C19," ","+")&"+"&TEXT(D19,"d+mmmm+yyyy")&"+to+"&TEXT(I19,"d+mmmm+yyyy")))) | S19: =IF(J19<>0,PRODUCT(J19,F19),"") | T19: =IF(NOT(AND($C19<>"",ISNUMBER(MATCH($C19,loc_list,0)),ISNUMBER($F19),$F19>0,OR(N($G19)>0,$H19<>""))),"",N($K19)*$F19) | U19: =IF(NOT(AND($C19<>"",ISNUMBER(MATCH($C19,loc_list,0)),ISNUMBER($F19),$F19>0,OR(N($G19)>0,$H19<>""))),"",IF(COUNT($O19:$T19)<4,"",SUM($O19:$T19))) | V19: =IF($C19="","",IF(NOT(ISNUMBER(MATCH($C19,loc_list,0))),"Destination not recognised. Choose one from the dropdown.",IF(NOT(ISNUMBER($F19)),"Enter the number of travellers.",IF($F19<=0,"Travellers must be 1 or more.",IF(AND(N($G19)<=0,$H19=""),"Enter the number of nights. For a day of travel with no overnight, set the final-day column — choose None if no subsistence is claimed.",IF(NOT(ISNUMBER(IFERROR(INDEX(fx_budget,MATCH($M19,fx_ccy,0)),""))),"No exchange rate for "&$M19&IF($M19=$N19,""," (the meals currency)")&". Add one on the FX sheet.",IF(AND(N($N19)>0,NOT(ISNUMBER(IFERROR(INDEX(fx_budget,MATCH($N19,fx_ccy,0)),"")))),"No exchange rate for "&$N19&" (the room-rate currency). Add one on the FX sheet.",IF(NOT(ISNUMBER($G19)),"Enter a quoted fare or search for one using the Google Flights link!",IF($M19<>$N19,"Dual currency: meals in "&$M19&", room rate in "&$N19&". Converted separately.","")))))))))
E20: =IF(D20<>"",_xlfn.XLOOKUP(MONTH(D20),Table2[Month Number],month_list,"",0,1),"") | I20: =IF(D20<>0,SUM(D20,G20),"") | L20: =IF($C20="","",IFERROR(INDEX(rates_tbl,MATCH($C20,loc_list,0),3),"")) | M20: =IF($C20="","",IFERROR(INDEX(rates_tbl,MATCH($C20,loc_list,0),4),"")) | N20: =IF($C20="","",IFERROR(INDEX(rates_tbl,MATCH($C20,loc_list,0),5),"")) | O20: =IF(NOT(AND($C20<>"",ISNUMBER(MATCH($C20,loc_list,0)),ISNUMBER($F20),$F20>0,OR(N($G20)>0,$H20<>""))),"",IF(N($G20)<=0,0,IF(NOT(ISNUMBER(IFERROR(INDEX(fx_budget,MATCH($N20,fx_ccy,0)),""))),"",N($G20)*INDEX(rates_tbl,MATCH($C20,loc_list,0),10)*$F20/IFERROR(INDEX(fx_budget,MATCH($N20,fx_ccy,0)),"")))) | P20: =IF(NOT(AND($C20<>"",ISNUMBER(MATCH($C20,loc_list,0)),ISNUMBER($F20),$F20>0,OR(N($G20)>0,$H20<>""))),"",IF(NOT(ISNUMBER(IFERROR(INDEX(fx_budget,MATCH($M20,fx_ccy,0)),""))),"",(N($G20)*INDEX(rates_tbl,MATCH($C20,loc_list,0),9)+IF($H20="Over 10 hours",INDEX(rates_tbl,MATCH($C20,loc_list,0),8),IF($H20="Over 5 hours",INDEX(rates_tbl,MATCH($C20,loc_list,0),7),0)))*$F20/IFERROR(INDEX(fx_budget,MATCH($M20,fx_ccy,0)),""))) | Q20: =IF(LEN(R20)-LEN(SUBSTITUTE(R20,"+",""))>=4, HYPERLINK(R20, _xlfn.TEXTJOIN(" ",TRUE,"Click for Google Flights Prices for",IF(B20="","London",IFERROR(_xlfn.TEXTBEFORE(B20,", "),B20)),"to",IFERROR(_xlfn.TEXTBEFORE(C20,", "),C20))), "") | R20: =HYPERLINK((IF(OR(C20="",D20="",I20=""),"","https://www.google.com/search?q=flights+from+"&SUBSTITUTE(IF(B20="","London, UK",B20)," ","+")&"+to+"&SUBSTITUTE(C20," ","+")&"+"&TEXT(D20,"d+mmmm+yyyy")&"+to+"&TEXT(I20,"d+mmmm+yyyy")))) | S20: =IF(J20<>0,PRODUCT(J20,F20),"") | T20: =IF(NOT(AND($C20<>"",ISNUMBER(MATCH($C20,loc_list,0)),ISNUMBER($F20),$F20>0,OR(N($G20)>0,$H20<>""))),"",N($K20)*$F20) | U20: =IF(NOT(AND($C20<>"",ISNUMBER(MATCH($C20,loc_list,0)),ISNUMBER($F20),$F20>0,OR(N($G20)>0,$H20<>""))),"",IF(COUNT($O20:$T20)<4,"",SUM($O20:$T20))) | V20: =IF($C20="","",IF(NOT(ISNUMBER(MATCH($C20,loc_list,0))),"Destination not recognised. Choose one from the dropdown.",IF(NOT(ISNUMBER($F20)),"Enter the number of travellers.",IF($F20<=0,"Travellers must be 1 or more.",IF(AND(N($G20)<=0,$H20=""),"Enter the number of nights. For a day of travel with no overnight, set the final-day column — choose None if no subsistence is claimed.",IF(NOT(ISNUMBER(IFERROR(INDEX(fx_budget,MATCH($M20,fx_ccy,0)),""))),"No exchange rate for "&$M20&IF($M20=$N20,""," (the meals currency)")&". Add one on the FX sheet.",IF(AND(N($N20)>0,NOT(ISNUMBER(IFERROR(INDEX(fx_budget,MATCH($N20,fx_ccy,0)),"")))),"No exchange rate for "&$N20&" (the room-rate currency). Add one on the FX sheet.",IF(NOT(ISNUMBER($G20)),"Enter a quoted fare or search for one using the Google Flights link!",IF($M20<>$N20,"Dual currency: meals in "&$M20&", room rate in "&$N20&". Converted separately.","")))))))))
E21: =IF(D21<>"",_xlfn.XLOOKUP(MONTH(D21),Table2[Month Number],month_list,"",0,1),"") | I21: =IF(D21<>0,SUM(D21,G21),"") | L21: =IF($C21="","",IFERROR(INDEX(rates_tbl,MATCH($C21,loc_list,0),3),"")) | M21: =IF($C21="","",IFERROR(INDEX(rates_tbl,MATCH($C21,loc_list,0),4),"")) | N21: =IF($C21="","",IFERROR(INDEX(rates_tbl,MATCH($C21,loc_list,0),5),"")) | O21: =IF(NOT(AND($C21<>"",ISNUMBER(MATCH($C21,loc_list,0)),ISNUMBER($F21),$F21>0,OR(N($G21)>0,$H21<>""))),"",IF(N($G21)<=0,0,IF(NOT(ISNUMBER(IFERROR(INDEX(fx_budget,MATCH($N21,fx_ccy,0)),""))),"",N($G21)*INDEX(rates_tbl,MATCH($C21,loc_list,0),10)*$F21/IFERROR(INDEX(fx_budget,MATCH($N21,fx_ccy,0)),"")))) | P21: =IF(NOT(AND($C21<>"",ISNUMBER(MATCH($C21,loc_list,0)),ISNUMBER($F21),$F21>0,OR(N($G21)>0,$H21<>""))),"",IF(NOT(ISNUMBER(IFERROR(INDEX(fx_budget,MATCH($M21,fx_ccy,0)),""))),"",(N($G21)*INDEX(rates_tbl,MATCH($C21,loc_list,0),9)+IF($H21="Over 10 hours",INDEX(rates_tbl,MATCH($C21,loc_list,0),8),IF($H21="Over 5 hours",INDEX(rates_tbl,MATCH($C21,loc_list,0),7),0)))*$F21/IFERROR(INDEX(fx_budget,MATCH($M21,fx_ccy,0)),""))) | Q21: =IF(LEN(R21)-LEN(SUBSTITUTE(R21,"+",""))>=4, HYPERLINK(R21, _xlfn.TEXTJOIN(" ",TRUE,"Click for Google Flights Prices for",IF(B21="","London",IFERROR(_xlfn.TEXTBEFORE(B21,", "),B21)),"to",IFERROR(_xlfn.TEXTBEFORE(C21,", "),C21))), "") | R21: =HYPERLINK((IF(OR(C21="",D21="",I21=""),"","https://www.google.com/search?q=flights+from+"&SUBSTITUTE(IF(B21="","London, UK",B21)," ","+")&"+to+"&SUBSTITUTE(C21," ","+")&"+"&TEXT(D21,"d+mmmm+yyyy")&"+to+"&TEXT(I21,"d+mmmm+yyyy")))) | S21: =IF(J21<>0,PRODUCT(J21,F21),"") | T21: =IF(NOT(AND($C21<>"",ISNUMBER(MATCH($C21,loc_list,0)),ISNUMBER($F21),$F21>0,OR(N($G21)>0,$H21<>""))),"",N($K21)*$F21) | U21: =IF(NOT(AND($C21<>"",ISNUMBER(MATCH($C21,loc_list,0)),ISNUMBER($F21),$F21>0,OR(N($G21)>0,$H21<>""))),"",IF(COUNT($O21:$T21)<4,"",SUM($O21:$T21))) | V21: =IF($C21="","",IF(NOT(ISNUMBER(MATCH($C21,loc_list,0))),"Destination not recognised. Choose one from the dropdown.",IF(NOT(ISNUMBER($F21)),"Enter the number of travellers.",IF($F21<=0,"Travellers must be 1 or more.",IF(AND(N($G21)<=0,$H21=""),"Enter the number of nights. For a day of travel with no overnight, set the final-day column — choose None if no subsistence is claimed.",IF(NOT(ISNUMBER(IFERROR(INDEX(fx_budget,MATCH($M21,fx_ccy,0)),""))),"No exchange rate for "&$M21&IF($M21=$N21,""," (the meals currency)")&". Add one on the FX sheet.",IF(AND(N($N21)>0,NOT(ISNUMBER(IFERROR(INDEX(fx_budget,MATCH($N21,fx_ccy,0)),"")))),"No exchange rate for "&$N21&" (the room-rate currency). Add one on the FX sheet.",IF(NOT(ISNUMBER($G21)),"Enter a quoted fare or search for one using the Google Flights link!",IF($M21<>$N21,"Dual currency: meals in "&$M21&", room rate in "&$N21&". Converted separately.","")))))))))
E22: =IF(D22<>"",_xlfn.XLOOKUP(MONTH(D22),Table2[Month Number],month_list,"",0,1),"") | I22: =IF(D22<>0,SUM(D22,G22),"") | L22: =IF($C22="","",IFERROR(INDEX(rates_tbl,MATCH($C22,loc_list,0),3),"")) | M22: =IF($C22="","",IFERROR(INDEX(rates_tbl,MATCH($C22,loc_list,0),4),"")) | N22: =IF($C22="","",IFERROR(INDEX(rates_tbl,MATCH($C22,loc_list,0),5),"")) | O22: =IF(NOT(AND($C22<>"",ISNUMBER(MATCH($C22,loc_list,0)),ISNUMBER($F22),$F22>0,OR(N($G22)>0,$H22<>""))),"",IF(N($G22)<=0,0,IF(NOT(ISNUMBER(IFERROR(INDEX(fx_budget,MATCH($N22,fx_ccy,0)),""))),"",N($G22)*INDEX(rates_tbl,MATCH($C22,loc_list,0),10)*$F22/IFERROR(INDEX(fx_budget,MATCH($N22,fx_ccy,0)),"")))) | P22: =IF(NOT(AND($C22<>"",ISNUMBER(MATCH($C22,loc_list,0)),ISNUMBER($F22),$F22>0,OR(N($G22)>0,$H22<>""))),"",IF(NOT(ISNUMBER(IFERROR(INDEX(fx_budget,MATCH($M22,fx_ccy,0)),""))),"",(N($G22)*INDEX(rates_tbl,MATCH($C22,loc_list,0),9)+IF($H22="Over 10 hours",INDEX(rates_tbl,MATCH($C22,loc_list,0),8),IF($H22="Over 5 hours",INDEX(rates_tbl,MATCH($C22,loc_list,0),7),0)))*$F22/IFERROR(INDEX(fx_budget,MATCH($M22,fx_ccy,0)),""))) | Q22: =IF(LEN(R22)-LEN(SUBSTITUTE(R22,"+",""))>=4, HYPERLINK(R22, _xlfn.TEXTJOIN(" ",TRUE,"Click for Google Flights Prices for",IF(B22="","London",IFERROR(_xlfn.TEXTBEFORE(B22,", "),B22)),"to",IFERROR(_xlfn.TEXTBEFORE(C22,", "),C22))), "") | R22: =HYPERLINK((IF(OR(C22="",D22="",I22=""),"","https://www.google.com/search?q=flights+from+"&SUBSTITUTE(IF(B22="","London, UK",B22)," ","+")&"+to+"&SUBSTITUTE(C22," ","+")&"+"&TEXT(D22,"d+mmmm+yyyy")&"+to+"&TEXT(I22,"d+mmmm+yyyy")))) | S22: =IF(J22<>0,PRODUCT(J22,F22),"") | T22: =IF(NOT(AND($C22<>"",ISNUMBER(MATCH($C22,loc_list,0)),ISNUMBER($F22),$F22>0,OR(N($G22)>0,$H22<>""))),"",N($K22)*$F22) | U22: =IF(NOT(AND($C22<>"",ISNUMBER(MATCH($C22,loc_list,0)),ISNUMBER($F22),$F22>0,OR(N($G22)>0,$H22<>""))),"",IF(COUNT($O22:$T22)<4,"",SUM($O22:$T22))) | V22: =IF($C22="","",IF(NOT(ISNUMBER(MATCH($C22,loc_list,0))),"Destination not recognised. Choose one from the dropdown.",IF(NOT(ISNUMBER($F22)),"Enter the number of travellers.",IF($F22<=0,"Travellers must be 1 or more.",IF(AND(N($G22)<=0,$H22=""),"Enter the number of nights. For a day of travel with no overnight, set the final-day column — choose None if no subsistence is claimed.",IF(NOT(ISNUMBER(IFERROR(INDEX(fx_budget,MATCH($M22,fx_ccy,0)),""))),"No exchange rate for "&$M22&IF($M22=$N22,""," (the meals currency)")&". Add one on the FX sheet.",IF(AND(N($N22)>0,NOT(ISNUMBER(IFERROR(INDEX(fx_budget,MATCH($N22,fx_ccy,0)),"")))),"No exchange rate for "&$N22&" (the room-rate currency). Add one on the FX sheet.",IF(NOT(ISNUMBER($G22)),"Enter a quoted fare or search for one using the Google Flights link!",IF($M22<>$N22,"Dual currency: meals in "&$M22&", room rate in "&$N22&". Converted separately.","")))))))))
E23: =IF(D23<>"",_xlfn.XLOOKUP(MONTH(D23),Table2[Month Number],month_list,"",0,1),"") | I23: =IF(D23<>0,SUM(D23,G23),"") | L23: =IF($C23="","",IFERROR(INDEX(rates_tbl,MATCH($C23,loc_list,0),3),"")) | M23: =IF($C23="","",IFERROR(INDEX(rates_tbl,MATCH($C23,loc_list,0),4),"")) | N23: =IF($C23="","",IFERROR(INDEX(rates_tbl,MATCH($C23,loc_list,0),5),"")) | O23: =IF(NOT(AND($C23<>"",ISNUMBER(MATCH($C23,loc_list,0)),ISNUMBER($F23),$F23>0,OR(N($G23)>0,$H23<>""))),"",IF(N($G23)<=0,0,IF(NOT(ISNUMBER(IFERROR(INDEX(fx_budget,MATCH($N23,fx_ccy,0)),""))),"",N($G23)*INDEX(rates_tbl,MATCH($C23,loc_list,0),10)*$F23/IFERROR(INDEX(fx_budget,MATCH($N23,fx_ccy,0)),"")))) | P23: =IF(NOT(AND($C23<>"",ISNUMBER(MATCH($C23,loc_list,0)),ISNUMBER($F23),$F23>0,OR(N($G23)>0,$H23<>""))),"",IF(NOT(ISNUMBER(IFERROR(INDEX(fx_budget,MATCH($M23,fx_ccy,0)),""))),"",(N($G23)*INDEX(rates_tbl,MATCH($C23,loc_list,0),9)+IF($H23="Over 10 hours",INDEX(rates_tbl,MATCH($C23,loc_list,0),8),IF($H23="Over 5 hours",INDEX(rates_tbl,MATCH($C23,loc_list,0),7),0)))*$F23/IFERROR(INDEX(fx_budget,MATCH($M23,fx_ccy,0)),""))) | Q23: =IF(LEN(R23)-LEN(SUBSTITUTE(R23,"+",""))>=4, HYPERLINK(R23, _xlfn.TEXTJOIN(" ",TRUE,"Click for Google Flights Prices for",IF(B23="","London",IFERROR(_xlfn.TEXTBEFORE(B23,", "),B23)),"to",IFERROR(_xlfn.TEXTBEFORE(C23,", "),C23))), "") | R23: =HYPERLINK((IF(OR(C23="",D23="",I23=""),"","https://www.google.com/search?q=flights+from+"&SUBSTITUTE(IF(B23="","London, UK",B23)," ","+")&"+to+"&SUBSTITUTE(C23," ","+")&"+"&TEXT(D23,"d+mmmm+yyyy")&"+to+"&TEXT(I23,"d+mmmm+yyyy")))) | S23: =IF(J23<>0,PRODUCT(J23,F23),"") | T23: =IF(NOT(AND($C23<>"",ISNUMBER(MATCH($C23,loc_list,0)),ISNUMBER($F23),$F23>0,OR(N($G23)>0,$H23<>""))),"",N($K23)*$F23) | U23: =IF(NOT(AND($C23<>"",ISNUMBER(MATCH($C23,loc_list,0)),ISNUMBER($F23),$F23>0,OR(N($G23)>0,$H23<>""))),"",IF(COUNT($O23:$T23)<4,"",SUM($O23:$T23))) | V23: =IF($C23="","",IF(NOT(ISNUMBER(MATCH($C23,loc_list,0))),"Destination not recognised. Choose one from the dropdown.",IF(NOT(ISNUMBER($F23)),"Enter the number of travellers.",IF($F23<=0,"Travellers must be 1 or more.",IF(AND(N($G23)<=0,$H23=""),"Enter the number of nights. For a day of travel with no overnight, set the final-day column — choose None if no subsistence is claimed.",IF(NOT(ISNUMBER(IFERROR(INDEX(fx_budget,MATCH($M23,fx_ccy,0)),""))),"No exchange rate for "&$M23&IF($M23=$N23,""," (the meals currency)")&". Add one on the FX sheet.",IF(AND(N($N23)>0,NOT(ISNUMBER(IFERROR(INDEX(fx_budget,MATCH($N23,fx_ccy,0)),"")))),"No exchange rate for "&$N23&" (the room-rate currency). Add one on the FX sheet.",IF(NOT(ISNUMBER($G23)),"Enter a quoted fare or search for one using the Google Flights link!",IF($M23<>$N23,"Dual currency: meals in "&$M23&", room rate in "&$N23&". Converted separately.","")))))))))
E24: =IF(D24<>"",_xlfn.XLOOKUP(MONTH(D24),Table2[Month Number],month_list,"",0,1),"") | I24: =IF(D24<>0,SUM(D24,G24),"") | L24: =IF($C24="","",IFERROR(INDEX(rates_tbl,MATCH($C24,loc_list,0),3),"")) | M24: =IF($C24="","",IFERROR(INDEX(rates_tbl,MATCH($C24,loc_list,0),4),"")) | N24: =IF($C24="","",IFERROR(INDEX(rates_tbl,MATCH($C24,loc_list,0),5),"")) | O24: =IF(NOT(AND($C24<>"",ISNUMBER(MATCH($C24,loc_list,0)),ISNUMBER($F24),$F24>0,OR(N($G24)>0,$H24<>""))),"",IF(N($G24)<=0,0,IF(NOT(ISNUMBER(IFERROR(INDEX(fx_budget,MATCH($N24,fx_ccy,0)),""))),"",N($G24)*INDEX(rates_tbl,MATCH($C24,loc_list,0),10)*$F24/IFERROR(INDEX(fx_budget,MATCH($N24,fx_ccy,0)),"")))) | P24: =IF(NOT(AND($C24<>"",ISNUMBER(MATCH($C24,loc_list,0)),ISNUMBER($F24),$F24>0,OR(N($G24)>0,$H24<>""))),"",IF(NOT(ISNUMBER(IFERROR(INDEX(fx_budget,MATCH($M24,fx_ccy,0)),""))),"",(N($G24)*INDEX(rates_tbl,MATCH($C24,loc_list,0),9)+IF($H24="Over 10 hours",INDEX(rates_tbl,MATCH($C24,loc_list,0),8),IF($H24="Over 5 hours",INDEX(rates_tbl,MATCH($C24,loc_list,0),7),0)))*$F24/IFERROR(INDEX(fx_budget,MATCH($M24,fx_ccy,0)),""))) | Q24: =IF(LEN(R24)-LEN(SUBSTITUTE(R24,"+",""))>=4, HYPERLINK(R24, _xlfn.TEXTJOIN(" ",TRUE,"Click for Google Flights Prices for",IF(B24="","London",IFERROR(_xlfn.TEXTBEFORE(B24,", "),B24)),"to",IFERROR(_xlfn.TEXTBEFORE(C24,", "),C24))), "") | R24: =HYPERLINK((IF(OR(C24="",D24="",I24=""),"","https://www.google.com/search?q=flights+from+"&SUBSTITUTE(IF(B24="","London, UK",B24)," ","+")&"+to+"&SUBSTITUTE(C24," ","+")&"+"&TEXT(D24,"d+mmmm+yyyy")&"+to+"&TEXT(I24,"d+mmmm+yyyy")))) | S24: =IF(J24<>0,PRODUCT(J24,F24),"") | T24: =IF(NOT(AND($C24<>"",ISNUMBER(MATCH($C24,loc_list,0)),ISNUMBER($F24),$F24>0,OR(N($G24)>0,$H24<>""))),"",N($K24)*$F24) | U24: =IF(NOT(AND($C24<>"",ISNUMBER(MATCH($C24,loc_list,0)),ISNUMBER($F24),$F24>0,OR(N($G24)>0,$H24<>""))),"",IF(COUNT($O24:$T24)<4,"",SUM($O24:$T24))) | V24: =IF($C24="","",IF(NOT(ISNUMBER(MATCH($C24,loc_list,0))),"Destination not recognised. Choose one from the dropdown.",IF(NOT(ISNUMBER($F24)),"Enter the number of travellers.",IF($F24<=0,"Travellers must be 1 or more.",IF(AND(N($G24)<=0,$H24=""),"Enter the number of nights. For a day of travel with no overnight, set the final-day column — choose None if no subsistence is claimed.",IF(NOT(ISNUMBER(IFERROR(INDEX(fx_budget,MATCH($M24,fx_ccy,0)),""))),"No exchange rate for "&$M24&IF($M24=$N24,""," (the meals currency)")&". Add one on the FX sheet.",IF(AND(N($N24)>0,NOT(ISNUMBER(IFERROR(INDEX(fx_budget,MATCH($N24,fx_ccy,0)),"")))),"No exchange rate for "&$N24&" (the room-rate currency). Add one on the FX sheet.",IF(NOT(ISNUMBER($G24)),"Enter a quoted fare or search for one using the Google Flights link!",IF($M24<>$N24,"Dual currency: meals in "&$M24&", room rate in "&$N24&". Converted separately.","")))))))))
E25: =IF(D25<>"",_xlfn.XLOOKUP(MONTH(D25),Table2[Month Number],month_list,"",0,1),"") | I25: =IF(D25<>0,SUM(D25,G25),"") | L25: =IF($C25="","",IFERROR(INDEX(rates_tbl,MATCH($C25,loc_list,0),3),"")) | M25: =IF($C25="","",IFERROR(INDEX(rates_tbl,MATCH($C25,loc_list,0),4),"")) | N25: =IF($C25="","",IFERROR(INDEX(rates_tbl,MATCH($C25,loc_list,0),5),"")) | O25: =IF(NOT(AND($C25<>"",ISNUMBER(MATCH($C25,loc_list,0)),ISNUMBER($F25),$F25>0,OR(N($G25)>0,$H25<>""))),"",IF(N($G25)<=0,0,IF(NOT(ISNUMBER(IFERROR(INDEX(fx_budget,MATCH($N25,fx_ccy,0)),""))),"",N($G25)*INDEX(rates_tbl,MATCH($C25,loc_list,0),10)*$F25/IFERROR(INDEX(fx_budget,MATCH($N25,fx_ccy,0)),"")))) | P25: =IF(NOT(AND($C25<>"",ISNUMBER(MATCH($C25,loc_list,0)),ISNUMBER($F25),$F25>0,OR(N($G25)>0,$H25<>""))),"",IF(NOT(ISNUMBER(IFERROR(INDEX(fx_budget,MATCH($M25,fx_ccy,0)),""))),"",(N($G25)*INDEX(rates_tbl,MATCH($C25,loc_list,0),9)+IF($H25="Over 10 hours",INDEX(rates_tbl,MATCH($C25,loc_list,0),8),IF($H25="Over 5 hours",INDEX(rates_tbl,MATCH($C25,loc_list,0),7),0)))*$F25/IFERROR(INDEX(fx_budget,MATCH($M25,fx_ccy,0)),""))) | Q25: =IF(LEN(R25)-LEN(SUBSTITUTE(R25,"+",""))>=4, HYPERLINK(R25, _xlfn.TEXTJOIN(" ",TRUE,"Click for Google Flights Prices for",IF(B25="","London",IFERROR(_xlfn.TEXTBEFORE(B25,", "),B25)),"to",IFERROR(_xlfn.TEXTBEFORE(C25,", "),C25))), "") | R25: =HYPERLINK((IF(OR(C25="",D25="",I25=""),"","https://www.google.com/search?q=flights+from+"&SUBSTITUTE(IF(B25="","London, UK",B25)," ","+")&"+to+"&SUBSTITUTE(C25," ","+")&"+"&TEXT(D25,"d+mmmm+yyyy")&"+to+"&TEXT(I25,"d+mmmm+yyyy")))) | S25: =IF(J25<>0,PRODUCT(J25,F25),"") | T25: =IF(NOT(AND($C25<>"",ISNUMBER(MATCH($C25,loc_list,0)),ISNUMBER($F25),$F25>0,OR(N($G25)>0,$H25<>""))),"",N($K25)*$F25) | U25: =IF(NOT(AND($C25<>"",ISNUMBER(MATCH($C25,loc_list,0)),ISNUMBER($F25),$F25>0,OR(N($G25)>0,$H25<>""))),"",IF(COUNT($O25:$T25)<4,"",SUM($O25:$T25))) | V25: =IF($C25="","",IF(NOT(ISNUMBER(MATCH($C25,loc_list,0))),"Destination not recognised. Choose one from the dropdown.",IF(NOT(ISNUMBER($F25)),"Enter the number of travellers.",IF($F25<=0,"Travellers must be 1 or more.",IF(AND(N($G25)<=0,$H25=""),"Enter the number of nights. For a day of travel with no overnight, set the final-day column — choose None if no subsistence is claimed.",IF(NOT(ISNUMBER(IFERROR(INDEX(fx_budget,MATCH($M25,fx_ccy,0)),""))),"No exchange rate for "&$M25&IF($M25=$N25,""," (the meals currency)")&". Add one on the FX sheet.",IF(AND(N($N25)>0,NOT(ISNUMBER(IFERROR(INDEX(fx_budget,MATCH($N25,fx_ccy,0)),"")))),"No exchange rate for "&$N25&" (the room-rate currency). Add one on the FX sheet.",IF(NOT(ISNUMBER($G25)),"Enter a quoted fare or search for one using the Google Flights link!",IF($M25<>$N25,"Dual currency: meals in "&$M25&", room rate in "&$N25&". Converted separately.","")))))))))
E26: =IF(D26<>"",_xlfn.XLOOKUP(MONTH(D26),Table2[Month Number],month_list,"",0,1),"") | I26: =IF(D26<>0,SUM(D26,G26),"") | L26: =IF($C26="","",IFERROR(INDEX(rates_tbl,MATCH($C26,loc_list,0),3),"")) | M26: =IF($C26="","",IFERROR(INDEX(rates_tbl,MATCH($C26,loc_list,0),4),"")) | N26: =IF($C26="","",IFERROR(INDEX(rates_tbl,MATCH($C26,loc_list,0),5),"")) | O26: =IF(NOT(AND($C26<>"",ISNUMBER(MATCH($C26,loc_list,0)),ISNUMBER($F26),$F26>0,OR(N($G26)>0,$H26<>""))),"",IF(N($G26)<=0,0,IF(NOT(ISNUMBER(IFERROR(INDEX(fx_budget,MATCH($N26,fx_ccy,0)),""))),"",N($G26)*INDEX(rates_tbl,MATCH($C26,loc_list,0),10)*$F26/IFERROR(INDEX(fx_budget,MATCH($N26,fx_ccy,0)),"")))) | P26: =IF(NOT(AND($C26<>"",ISNUMBER(MATCH($C26,loc_list,0)),ISNUMBER($F26),$F26>0,OR(N($G26)>0,$H26<>""))),"",IF(NOT(ISNUMBER(IFERROR(INDEX(fx_budget,MATCH($M26,fx_ccy,0)),""))),"",(N($G26)*INDEX(rates_tbl,MATCH($C26,loc_list,0),9)+IF($H26="Over 10 hours",INDEX(rates_tbl,MATCH($C26,loc_list,0),8),IF($H26="Over 5 hours",INDEX(rates_tbl,MATCH($C26,loc_list,0),7),0)))*$F26/IFERROR(INDEX(fx_budget,MATCH($M26,fx_ccy,0)),""))) | Q26: =IF(LEN(R26)-LEN(SUBSTITUTE(R26,"+",""))>=4, HYPERLINK(R26, _xlfn.TEXTJOIN(" ",TRUE,"Click for Google Flights Prices for",IF(B26="","London",IFERROR(_xlfn.TEXTBEFORE(B26,", "),B26)),"to",IFERROR(_xlfn.TEXTBEFORE(C26,", "),C26))), "") | R26: =HYPERLINK((IF(OR(C26="",D26="",I26=""),"","https://www.google.com/search?q=flights+from+"&SUBSTITUTE(IF(B26="","London, UK",B26)," ","+")&"+to+"&SUBSTITUTE(C26," ","+")&"+"&TEXT(D26,"d+mmmm+yyyy")&"+to+"&TEXT(I26,"d+mmmm+yyyy")))) | S26: =IF(J26<>0,PRODUCT(J26,F26),"") | T26: =IF(NOT(AND($C26<>"",ISNUMBER(MATCH($C26,loc_list,0)),ISNUMBER($F26),$F26>0,OR(N($G26)>0,$H26<>""))),"",N($K26)*$F26) | U26: =IF(NOT(AND($C26<>"",ISNUMBER(MATCH($C26,loc_list,0)),ISNUMBER($F26),$F26>0,OR(N($G26)>0,$H26<>""))),"",IF(COUNT($O26:$T26)<4,"",SUM($O26:$T26))) | V26: =IF($C26="","",IF(NOT(ISNUMBER(MATCH($C26,loc_list,0))),"Destination not recognised. Choose one from the dropdown.",IF(NOT(ISNUMBER($F26)),"Enter the number of travellers.",IF($F26<=0,"Travellers must be 1 or more.",IF(AND(N($G26)<=0,$H26=""),"Enter the number of nights. For a day of travel with no overnight, set the final-day column — choose None if no subsistence is claimed.",IF(NOT(ISNUMBER(IFERROR(INDEX(fx_budget,MATCH($M26,fx_ccy,0)),""))),"No exchange rate for "&$M26&IF($M26=$N26,""," (the meals currency)")&". Add one on the FX sheet.",IF(AND(N($N26)>0,NOT(ISNUMBER(IFERROR(INDEX(fx_budget,MATCH($N26,fx_ccy,0)),"")))),"No exchange rate for "&$N26&" (the room-rate currency). Add one on the FX sheet.",IF(NOT(ISNUMBER($G26)),"Enter a quoted fare or search for one using the Google Flights link!",IF($M26<>$N26,"Dual currency: meals in "&$M26&", room rate in "&$N26&". Converted separately.","")))))))))
E27: =IF(D27<>"",_xlfn.XLOOKUP(MONTH(D27),Table2[Month Number],month_list,"",0,1),"") | I27: =IF(D27<>0,SUM(D27,G27),"") | L27: =IF($C27="","",IFERROR(INDEX(rates_tbl,MATCH($C27,loc_list,0),3),"")) | M27: =IF($C27="","",IFERROR(INDEX(rates_tbl,MATCH($C27,loc_list,0),4),"")) | N27: =IF($C27="","",IFERROR(INDEX(rates_tbl,MATCH($C27,loc_list,0),5),"")) | O27: =IF(NOT(AND($C27<>"",ISNUMBER(MATCH($C27,loc_list,0)),ISNUMBER($F27),$F27>0,OR(N($G27)>0,$H27<>""))),"",IF(N($G27)<=0,0,IF(NOT(ISNUMBER(IFERROR(INDEX(fx_budget,MATCH($N27,fx_ccy,0)),""))),"",N($G27)*INDEX(rates_tbl,MATCH($C27,loc_list,0),10)*$F27/IFERROR(INDEX(fx_budget,MATCH($N27,fx_ccy,0)),"")))) | P27: =IF(NOT(AND($C27<>"",ISNUMBER(MATCH($C27,loc_list,0)),ISNUMBER($F27),$F27>0,OR(N($G27)>0,$H27<>""))),"",IF(NOT(ISNUMBER(IFERROR(INDEX(fx_budget,MATCH($M27,fx_ccy,0)),""))),"",(N($G27)*INDEX(rates_tbl,MATCH($C27,loc_list,0),9)+IF($H27="Over 10 hours",INDEX(rates_tbl,MATCH($C27,loc_list,0),8),IF($H27="Over 5 hours",INDEX(rates_tbl,MATCH($C27,loc_list,0),7),0)))*$F27/IFERROR(INDEX(fx_budget,MATCH($M27,fx_ccy,0)),""))) | Q27: =IF(LEN(R27)-LEN(SUBSTITUTE(R27,"+",""))>=4, HYPERLINK(R27, _xlfn.TEXTJOIN(" ",TRUE,"Click for Google Flights Prices for",IF(B27="","London",IFERROR(_xlfn.TEXTBEFORE(B27,", "),B27)),"to",IFERROR(_xlfn.TEXTBEFORE(C27,", "),C27))), "") | R27: =HYPERLINK((IF(OR(C27="",D27="",I27=""),"","https://www.google.com/search?q=flights+from+"&SUBSTITUTE(IF(B27="","London, UK",B27)," ","+")&"+to+"&SUBSTITUTE(C27," ","+")&"+"&TEXT(D27,"d+mmmm+yyyy")&"+to+"&TEXT(I27,"d+mmmm+yyyy")))) | S27: =IF(J27<>0,PRODUCT(J27,F27),"") | T27: =IF(NOT(AND($C27<>"",ISNUMBER(MATCH($C27,loc_list,0)),ISNUMBER($F27),$F27>0,OR(N($G27)>0,$H27<>""))),"",N($K27)*$F27) | U27: =IF(NOT(AND($C27<>"",ISNUMBER(MATCH($C27,loc_list,0)),ISNUMBER($F27),$F27>0,OR(N($G27)>0,$H27<>""))),"",IF(COUNT($O27:$T27)<4,"",SUM($O27:$T27))) | V27: =IF($C27="","",IF(NOT(ISNUMBER(MATCH($C27,loc_list,0))),"Destination not recognised. Choose one from the dropdown.",IF(NOT(ISNUMBER($F27)),"Enter the number of travellers.",IF($F27<=0,"Travellers must be 1 or more.",IF(AND(N($G27)<=0,$H27=""),"Enter the number of nights. For a day of travel with no overnight, set the final-day column — choose None if no subsistence is claimed.",IF(NOT(ISNUMBER(IFERROR(INDEX(fx_budget,MATCH($M27,fx_ccy,0)),""))),"No exchange rate for "&$M27&IF($M27=$N27,""," (the meals currency)")&". Add one on the FX sheet.",IF(AND(N($N27)>0,NOT(ISNUMBER(IFERROR(INDEX(fx_budget,MATCH($N27,fx_ccy,0)),"")))),"No exchange rate for "&$N27&" (the room-rate currency). Add one on the FX sheet.",IF(NOT(ISNUMBER($G27)),"Enter a quoted fare or search for one using the Google Flights link!",IF($M27<>$N27,"Dual currency: meals in "&$M27&", room rate in "&$N27&". Converted separately.","")))))))))
E28: =IF(D28<>"",_xlfn.XLOOKUP(MONTH(D28),Table2[Month Number],month_list,"",0,1),"") | I28: =IF(D28<>0,SUM(D28,G28),"") | L28: =IF($C28="","",IFERROR(INDEX(rates_tbl,MATCH($C28,loc_list,0),3),"")) | M28: =IF($C28="","",IFERROR(INDEX(rates_tbl,MATCH($C28,loc_list,0),4),"")) | N28: =IF($C28="","",IFERROR(INDEX(rates_tbl,MATCH($C28,loc_list,0),5),"")) | O28: =IF(NOT(AND($C28<>"",ISNUMBER(MATCH($C28,loc_list,0)),ISNUMBER($F28),$F28>0,OR(N($G28)>0,$H28<>""))),"",IF(N($G28)<=0,0,IF(NOT(ISNUMBER(IFERROR(INDEX(fx_budget,MATCH($N28,fx_ccy,0)),""))),"",N($G28)*INDEX(rates_tbl,MATCH($C28,loc_list,0),10)*$F28/IFERROR(INDEX(fx_budget,MATCH($N28,fx_ccy,0)),"")))) | P28: =IF(NOT(AND($C28<>"",ISNUMBER(MATCH($C28,loc_list,0)),ISNUMBER($F28),$F28>0,OR(N($G28)>0,$H28<>""))),"",IF(NOT(ISNUMBER(IFERROR(INDEX(fx_budget,MATCH($M28,fx_ccy,0)),""))),"",(N($G28)*INDEX(rates_tbl,MATCH($C28,loc_list,0),9)+IF($H28="Over 10 hours",INDEX(rates_tbl,MATCH($C28,loc_list,0),8),IF($H28="Over 5 hours",INDEX(rates_tbl,MATCH($C28,loc_list,0),7),0)))*$F28/IFERROR(INDEX(fx_budget,MATCH($M28,fx_ccy,0)),""))) | Q28: =IF(LEN(R28)-LEN(SUBSTITUTE(R28,"+",""))>=4, HYPERLINK(R28, _xlfn.TEXTJOIN(" ",TRUE,"Click for Google Flights Prices for",IF(B28="","London",IFERROR(_xlfn.TEXTBEFORE(B28,", "),B28)),"to",IFERROR(_xlfn.TEXTBEFORE(C28,", "),C28))), "") | R28: =HYPERLINK((IF(OR(C28="",D28="",I28=""),"","https://www.google.com/search?q=flights+from+"&SUBSTITUTE(IF(B28="","London, UK",B28)," ","+")&"+to+"&SUBSTITUTE(C28," ","+")&"+"&TEXT(D28,"d+mmmm+yyyy")&"+to+"&TEXT(I28,"d+mmmm+yyyy")))) | S28: =IF(J28<>0,PRODUCT(J28,F28),"") | T28: =IF(NOT(AND($C28<>"",ISNUMBER(MATCH($C28,loc_list,0)),ISNUMBER($F28),$F28>0,OR(N($G28)>0,$H28<>""))),"",N($K28)*$F28) | U28: =IF(NOT(AND($C28<>"",ISNUMBER(MATCH($C28,loc_list,0)),ISNUMBER($F28),$F28>0,OR(N($G28)>0,$H28<>""))),"",IF(COUNT($O28:$T28)<4,"",SUM($O28:$T28))) | V28: =IF($C28="","",IF(NOT(ISNUMBER(MATCH($C28,loc_list,0))),"Destination not recognised. Choose one from the dropdown.",IF(NOT(ISNUMBER($F28)),"Enter the number of travellers.",IF($F28<=0,"Travellers must be 1 or more.",IF(AND(N($G28)<=0,$H28=""),"Enter the number of nights. For a day of travel with no overnight, set the final-day column — choose None if no subsistence is claimed.",IF(NOT(ISNUMBER(IFERROR(INDEX(fx_budget,MATCH($M28,fx_ccy,0)),""))),"No exchange rate for "&$M28&IF($M28=$N28,""," (the meals currency)")&". Add one on the FX sheet.",IF(AND(N($N28)>0,NOT(ISNUMBER(IFERROR(INDEX(fx_budget,MATCH($N28,fx_ccy,0)),"")))),"No exchange rate for "&$N28&" (the room-rate currency). Add one on the FX sheet.",IF(NOT(ISNUMBER($G28)),"Enter a quoted fare or search for one using the Google Flights link!",IF($M28<>$N28,"Dual currency: meals in "&$M28&", room rate in "&$N28&". Converted separately.","")))))))))
E29: =IF(D29<>"",_xlfn.XLOOKUP(MONTH(D29),Table2[Month Number],month_list,"",0,1),"") | I29: =IF(D29<>0,SUM(D29,G29),"") | L29: =IF($C29="","",IFERROR(INDEX(rates_tbl,MATCH($C29,loc_list,0),3),"")) | M29: =IF($C29="","",IFERROR(INDEX(rates_tbl,MATCH($C29,loc_list,0),4),"")) | N29: =IF($C29="","",IFERROR(INDEX(rates_tbl,MATCH($C29,loc_list,0),5),"")) | O29: =IF(NOT(AND($C29<>"",ISNUMBER(MATCH($C29,loc_list,0)),ISNUMBER($F29),$F29>0,OR(N($G29)>0,$H29<>""))),"",IF(N($G29)<=0,0,IF(NOT(ISNUMBER(IFERROR(INDEX(fx_budget,MATCH($N29,fx_ccy,0)),""))),"",N($G29)*INDEX(rates_tbl,MATCH($C29,loc_list,0),10)*$F29/IFERROR(INDEX(fx_budget,MATCH($N29,fx_ccy,0)),"")))) | P29: =IF(NOT(AND($C29<>"",ISNUMBER(MATCH($C29,loc_list,0)),ISNUMBER($F29),$F29>0,OR(N($G29)>0,$H29<>""))),"",IF(NOT(ISNUMBER(IFERROR(INDEX(fx_budget,MATCH($M29,fx_ccy,0)),""))),"",(N($G29)*INDEX(rates_tbl,MATCH($C29,loc_list,0),9)+IF($H29="Over 10 hours",INDEX(rates_tbl,MATCH($C29,loc_list,0),8),IF($H29="Over 5 hours",INDEX(rates_tbl,MATCH($C29,loc_list,0),7),0)))*$F29/IFERROR(INDEX(fx_budget,MATCH($M29,fx_ccy,0)),""))) | Q29: =IF(LEN(R29)-LEN(SUBSTITUTE(R29,"+",""))>=4, HYPERLINK(R29, _xlfn.TEXTJOIN(" ",TRUE,"Click for Google Flights Prices for",IF(B29="","London",IFERROR(_xlfn.TEXTBEFORE(B29,", "),B29)),"to",IFERROR(_xlfn.TEXTBEFORE(C29,", "),C29))), "") | R29: =HYPERLINK((IF(OR(C29="",D29="",I29=""),"","https://www.google.com/search?q=flights+from+"&SUBSTITUTE(IF(B29="","London, UK",B29)," ","+")&"+to+"&SUBSTITUTE(C29," ","+")&"+"&TEXT(D29,"d+mmmm+yyyy")&"+to+"&TEXT(I29,"d+mmmm+yyyy")))) | S29: =IF(J29<>0,PRODUCT(J29,F29),"") | T29: =IF(NOT(AND($C29<>"",ISNUMBER(MATCH($C29,loc_list,0)),ISNUMBER($F29),$F29>0,OR(N($G29)>0,$H29<>""))),"",N($K29)*$F29) | U29: =IF(NOT(AND($C29<>"",ISNUMBER(MATCH($C29,loc_list,0)),ISNUMBER($F29),$F29>0,OR(N($G29)>0,$H29<>""))),"",IF(COUNT($O29:$T29)<4,"",SUM($O29:$T29))) | V29: =IF($C29="","",IF(NOT(ISNUMBER(MATCH($C29,loc_list,0))),"Destination not recognised. Choose one from the dropdown.",IF(NOT(ISNUMBER($F29)),"Enter the number of travellers.",IF($F29<=0,"Travellers must be 1 or more.",IF(AND(N($G29)<=0,$H29=""),"Enter the number of nights. For a day of travel with no overnight, set the final-day column — choose None if no subsistence is claimed.",IF(NOT(ISNUMBER(IFERROR(INDEX(fx_budget,MATCH($M29,fx_ccy,0)),""))),"No exchange rate for "&$M29&IF($M29=$N29,""," (the meals currency)")&". Add one on the FX sheet.",IF(AND(N($N29)>0,NOT(ISNUMBER(IFERROR(INDEX(fx_budget,MATCH($N29,fx_ccy,0)),"")))),"No exchange rate for "&$N29&" (the room-rate currency). Add one on the FX sheet.",IF(NOT(ISNUMBER($G29)),"Enter a quoted fare or search for one using the Google Flights link!",IF($M29<>$N29,"Dual currency: meals in "&$M29&", room rate in "&$N29&". Converted separately.","")))))))))
E30: =IF(D30<>"",_xlfn.XLOOKUP(MONTH(D30),Table2[Month Number],month_list,"",0,1),"") | I30: =IF(D30<>0,SUM(D30,G30),"") | L30: =IF($C30="","",IFERROR(INDEX(rates_tbl,MATCH($C30,loc_list,0),3),"")) | M30: =IF($C30="","",IFERROR(INDEX(rates_tbl,MATCH($C30,loc_list,0),4),"")) | N30: =IF($C30="","",IFERROR(INDEX(rates_tbl,MATCH($C30,loc_list,0),5),"")) | O30: =IF(NOT(AND($C30<>"",ISNUMBER(MATCH($C30,loc_list,0)),ISNUMBER($F30),$F30>0,OR(N($G30)>0,$H30<>""))),"",IF(N($G30)<=0,0,IF(NOT(ISNUMBER(IFERROR(INDEX(fx_budget,MATCH($N30,fx_ccy,0)),""))),"",N($G30)*INDEX(rates_tbl,MATCH($C30,loc_list,0),10)*$F30/IFERROR(INDEX(fx_budget,MATCH($N30,fx_ccy,0)),"")))) | P30: =IF(NOT(AND($C30<>"",ISNUMBER(MATCH($C30,loc_list,0)),ISNUMBER($F30),$F30>0,OR(N($G30)>0,$H30<>""))),"",IF(NOT(ISNUMBER(IFERROR(INDEX(fx_budget,MATCH($M30,fx_ccy,0)),""))),"",(N($G30)*INDEX(rates_tbl,MATCH($C30,loc_list,0),9)+IF($H30="Over 10 hours",INDEX(rates_tbl,MATCH($C30,loc_list,0),8),IF($H30="Over 5 hours",INDEX(rates_tbl,MATCH($C30,loc_list,0),7),0)))*$F30/IFERROR(INDEX(fx_budget,MATCH($M30,fx_ccy,0)),""))) | Q30: =IF(LEN(R30)-LEN(SUBSTITUTE(R30,"+",""))>=4, HYPERLINK(R30, _xlfn.TEXTJOIN(" ",TRUE,"Click for Google Flights Prices for",IF(B30="","London",IFERROR(_xlfn.TEXTBEFORE(B30,", "),B30)),"to",IFERROR(_xlfn.TEXTBEFORE(C30,", "),C30))), "") | R30: =HYPERLINK((IF(OR(C30="",D30="",I30=""),"","https://www.google.com/search?q=flights+from+"&SUBSTITUTE(IF(B30="","London, UK",B30)," ","+")&"+to+"&SUBSTITUTE(C30," ","+")&"+"&TEXT(D30,"d+mmmm+yyyy")&"+to+"&TEXT(I30,"d+mmmm+yyyy")))) | S30: =IF(J30<>0,PRODUCT(J30,F30),"") | T30: =IF(NOT(AND($C30<>"",ISNUMBER(MATCH($C30,loc_list,0)),ISNUMBER($F30),$F30>0,OR(N($G30)>0,$H30<>""))),"",N($K30)*$F30) | U30: =IF(NOT(AND($C30<>"",ISNUMBER(MATCH($C30,loc_list,0)),ISNUMBER($F30),$F30>0,OR(N($G30)>0,$H30<>""))),"",IF(COUNT($O30:$T30)<4,"",SUM($O30:$T30))) | V30: =IF($C30="","",IF(NOT(ISNUMBER(MATCH($C30,loc_list,0))),"Destination not recognised. Choose one from the dropdown.",IF(NOT(ISNUMBER($F30)),"Enter the number of travellers.",IF($F30<=0,"Travellers must be 1 or more.",IF(AND(N($G30)<=0,$H30=""),"Enter the number of nights. For a day of travel with no overnight, set the final-day column — choose None if no subsistence is claimed.",IF(NOT(ISNUMBER(IFERROR(INDEX(fx_budget,MATCH($M30,fx_ccy,0)),""))),"No exchange rate for "&$M30&IF($M30=$N30,""," (the meals currency)")&". Add one on the FX sheet.",IF(AND(N($N30)>0,NOT(ISNUMBER(IFERROR(INDEX(fx_budget,MATCH($N30,fx_ccy,0)),"")))),"No exchange rate for "&$N30&" (the room-rate currency). Add one on the FX sheet.",IF(NOT(ISNUMBER($G30)),"Enter a quoted fare or search for one using the Google Flights link!",IF($M30<>$N30,"Dual currency: meals in "&$M30&", room rate in "&$N30&". Converted separately.","")))))))))
... E40: =IF(D40<>"",_xlfn.XLOOKUP(MONTH(D40),Table2[Month Number],month_list,"",0,1),"") | I40: =IF(D40<>0,SUM(D40,G40),"") | L40: =IF($C40="","",IFERROR(INDEX(rates_tbl,MATCH($C40,loc_list,0),3),"")) | M40: =IF($C40="","",IFERROR(INDEX(rates_tbl,MATCH($C40,loc_list,0),4),"")) | N40: =IF($C40="","",IFERROR(INDEX(rates_tbl,MATCH($C40,loc_list,0),5),"")) | O40: =IF(NOT(AND($C40<>"",ISNUMBER(MATCH($C40,loc_list,0)),ISNUMBER($F40),$F40>0,OR(N($G40)>0,$H40<>""))),"",IF(N($G40)<=0,0,IF(NOT(ISNUMBER(IFERROR(INDEX(fx_budget,MATCH($N40,fx_ccy,0)),""))),"",N($G40)*INDEX(rates_tbl,MATCH($C40,loc_list,0),10)*$F40/IFERROR(INDEX(fx_budget,MATCH($N40,fx_ccy,0)),"")))) | P40: =IF(NOT(AND($C40<>"",ISNUMBER(MATCH($C40,loc_list,0)),ISNUMBER($F40),$F40>0,OR(N($G40)>0,$H40<>""))),"",IF(NOT(ISNUMBER(IFERROR(INDEX(fx_budget,MATCH($M40,fx_ccy,0)),""))),"",(N($G40)*INDEX(rates_tbl,MATCH($C40,loc_list,0),9)+IF($H40="Over 10 hours",INDEX(rates_tbl,MATCH($C40,loc_list,0),8),IF($H40="Over 5 hours",INDEX(rates_tbl,MATCH($C40,loc_list,0),7),0)))*$F40/IFERROR(INDEX(fx_budget,MATCH($M40,fx_ccy,0)),""))) | Q40: =IF(LEN(R40)-LEN(SUBSTITUTE(R40,"+",""))>=4, HYPERLINK(R40, _xlfn.TEXTJOIN(" ",TRUE,"Click for Google Flights Prices for",IF(B40="","London",IFERROR(_xlfn.TEXTBEFORE(B40,", "),B40)),"to",IFERROR(_xlfn.TEXTBEFORE(C40,", "),C40))), "") | R40: =HYPERLINK((IF(OR(C40="",D40="",I40=""),"","https://www.google.com/search?q=flights+from+"&SUBSTITUTE(IF(B40="","London, UK",B40)," ","+")&"+to+"&SUBSTITUTE(C40," ","+")&"+"&TEXT(D40,"d+mmmm+yyyy")&"+to+"&TEXT(I40,"d+mmmm+yyyy")))) | S40: =IF(J40<>0,PRODUCT(J40,F40),"") | T40: =IF(NOT(AND($C40<>"",ISNUMBER(MATCH($C40,loc_list,0)),ISNUMBER($F40),$F40>0,OR(N($G40)>0,$H40<>""))),"",N($K40)*$F40) | U40: =IF(NOT(AND($C40<>"",ISNUMBER(MATCH($C40,loc_list,0)),ISNUMBER($F40),$F40>0,OR(N($G40)>0,$H40<>""))),"",IF(COUNT($O40:$T40)<4,"",SUM($O40:$T40))) | V40: =IF($C40="","",IF(NOT(ISNUMBER(MATCH($C40,loc_list,0))),"Destination not recognised. Choose one from the dropdown.",IF(NOT(ISNUMBER($F40)),"Enter the number of travellers.",IF($F40<=0,"Travellers must be 1 or more.",IF(AND(N($G40)<=0,$H40=""),"Enter the number of nights. For a day of travel with no overnight, set the final-day column — choose None if no subsistence is claimed.",IF(NOT(ISNUMBER(IFERROR(INDEX(fx_budget,MATCH($M40,fx_ccy,0)),""))),"No exchange rate for "&$M40&IF($M40=$N40,""," (the meals currency)")&". Add one on the FX sheet.",IF(AND(N($N40)>0,NOT(ISNUMBER(IFERROR(INDEX(fx_budget,MATCH($N40,fx_ccy,0)),"")))),"No exchange rate for "&$N40&" (the room-rate currency). Add one on the FX sheet.",IF(NOT(ISNUMBER($G40)),"Enter a quoted fare or search for one using the Google Flights link!",IF($M40<>$N40,"Dual currency: meals in "&$M40&", room rate in "&$N40&". Converted separately.","")))))))))
A42: HMRC calculates the reimbursement amount for an overnight stay as: the costs of a room (hotel etc.) PLUS the 24 hour rate. Breakfast, lunch and dinner are taken as covered by the 24 hour rate. Use the final-day column only for a day of travel with no overnight stay (these rates don't include a room)
A43: Final Note: Although widely used as a reference point. HMRC scale rates do not represent a minimum standard for all employers or funders to abide by (they represent the maximum reimbursable amount that one can claim without receipts for tax purposes). Airfare, visas, insurance and ground transport are estimates or your own inputs. HMRC does not publish rates for any of these elements.

Sheet Rates
A1: Reference data - do not edit. Static tables, each with the date it was captured.
A2: Source: https://www.gov.uk/guidance/expenses-rates-for-employees-travelling-outside-the-uk
A3: HMRC overseas scale rates - 285 locations, 171 countries. Captured 26 August 2026. Maximum reimbursable without receipts for tax purposes; an employer or funder policy may be lower.
A4: Location | B4: Country | C4: Haul band | D4: Meals currency | E4: Room currency | F4: Dual currency | G4: Over 5 hours | H4: Over 10 hours | I4: 24 hour rate | J4: Room rate | K4: Breakfast | L4: Lunch | M4: Dinner | N4: Other | O4: Drinks | P4: Hotel to office | Q4: Total residual
A5: Abu Dhabi, United Arab Emirates | B5: United Arab Emirates | C5: 3 | D5: AED | E5: AED | G5: 98 | H5: 242.5 | I5: 373.5 | J5: 637 | K5: 85.5 | L5: 82 | M5: 128.5 | N5: 15 | O5: 32 | P5: 30.5 | Q5: 373.5
A6: Abuja, Nigeria | B6: Nigeria | C6: 3 | D6: NGN | E6: NGN | G6: 7644.5 | H6: 17836.5 | I6: 27529 | J6: 79560 | K6: 7233 | L6: 6986.5 | M6: 9534.5 | N6: 1068.5 | O6: 1315.5 | P6: 1391 | Q6: 27529
A7: Accra, Ghana | B7: Ghana | C7: 3 | D7: GHS | E7: USD | F7: Y | G7: 42.5 | H7: 127.5 | I7: 149.5 | J7: 200 | K7: 0 | L7: 38 | M7: 80.5 | N7: 5.5 | O7: 9 | P7: 16.5 | Q7: 149.5
A8: Addis Ababa, Ethiopia | B8: Ethiopia | C8: 3 | D8: ETB | E8: USD | F8: Y | G8: 677 | H8: 1548.5 | I8: 1719.5 | J8: 274.5 | K8: 0 | L8: 610 | M8: 805 | N8: 0 | O8: 133.5 | P8: 171 | Q8: 1719.5
A9: Adelaide, Australia | B9: Australia | C9: 6 | D9: AUD | E9: AUD | G9: 57 | H9: 133 | I9: 176 | J9: 262.5 | K9: 33.5 | L9: 51 | M9: 70.5 | N9: 0 | O9: 11.5 | P9: 9.5 | Q9: 176
A10: Agadir, Morocco | B10: Morocco | C10: 2 | D10: MAD | E10: MAD | G10: 209.5 | H10: 559.5 | I10: 648.5 | J10: 1304 | K10: 0 | L10: 183 | M10: 324 | N10: 37 | O10: 52.5 | P10: 52 | Q10: 648.5
A11: Ahmedabad, India | B11: India | C11: 3 | D11: INR | E11: INR | G11: 1016 | H11: 2212.5 | I11: 2753 | J11: 9420.5 | K11: 0 | L11: 893 | M11: 1073.5 | N11: 0 | O11: 246 | P11: 540.5 | Q11: 2753
A12: Al Khobar, Saudi Arabia | B12: Saudi Arabia | C12: 3 | D12: SAR | E12: SAR | G12: 114 | H12: 257 | I12: 374.5 | J12: 532.5 | K12: 78.5 | L12: 99.5 | M12: 129 | N12: 11.5 | O12: 28.5 | P12: 27.5 | Q12: 374.5
A13: Alexandria, Egypt | B13: Egypt | C13: 2 | D13: EGP | E13: EGP | G13: 154 | H13: 370.5 | I13: 445 | J13: 1118 | K13: 0 | L13: 138 | M13: 201 | N13: 0 | O13: 31.5 | P13: 74.5 | Q13: 445
A14: Algiers, Algeria | B14: Algeria | C14: 2 | D14: DZD | E14: DZD | G14: 2641.5 | H14: 7537.5 | I14: 9973 | J14: 23383.5 | K14: 1804 | L14: 2383.5 | M14: 4638.5 | N14: 0 | O14: 515.5 | P14: 631.5 | Q14: 9973
A15: Almaty, Kazakhstan | B15: Kazakhstan | C15: 3 | D15: KZT | E15: KZT | G15: 9460 | H15: 23650 | I15: 25036 | J15: 43626.5 | K15: 0 | L15: 8437 | M15: 13077 | N15: 0 | O15: 2226 | P15: 1386 | Q15: 25036
A16: Amman, Jordan | B16: Jordan | C16: 2 | D16: JOD | E16: JOD | G16: 30.5 | H16: 73.5 | I16: 84.5 | J16: 131.5 | K16: 0 | L16: 25.5 | M16: 38 | N16: 3.5 | O16: 10 | P16: 7.5 | Q16: 84.5
A17: Amsterdam, Netherlands | B17: Netherlands | C17: 1 | D17: EUR | E17: EUR | G17: 25 | H17: 65 | I17: 72 | J17: 150 | K17: 0 | L17: 22 | M17: 37.5 | N17: 0 | O17: 5.5 | P17: 7 | Q17: 72
A18: Anguilla, Anguilla | B18: Anguilla | C18: 4 | D18: USD | E18: USD | G18: 39 | H18: 122 | I18: 150.5 | J18: 235.5 | K18: 15.5 | L18: 31 | M18: 75.5 | N18: 4 | O18: 15.5 | P18: 9 | Q18: 150.5
A19: Ankara, Turkey | B19: Turkey | C19: 2 | D19: TRY | E19: EUR | F19: Y | G19: 93 | H19: 223.5 | I19: 239.5 | J19: 160 | K19: 0 | L19: 79.5 | M19: 117.5 | N19: 0 | O19: 26.5 | P19: 16 | Q19: 239.5
A20: Antananarivo, Madagascar | B20: Madagascar | C20: 4 | D20: MGA | E20: MGA | G20: 56012 | H20: 146819.5 | I20: 219663.5 | J20: 471687.5 | K20: 45828 | L20: 50920 | M20: 85715.5 | N20: 6789.5 | O20: 10184 | P20: 20226.5 | Q20: 219663.5
A21: Apia, Samoa | B21: Samoa | C21: 6 | D21: WST | E21: USD | F21: Y | G21: 63 | H21: 147 | I21: 205.5 | J21: 133 | K21: 28 | L21: 57 | M21: 78.5 | N21: 11.5 | O21: 11.5 | P21: 19 | Q21: 205.5
A22: Aqaba, Jordan | B22: Jordan | C22: 2 | D22: JOD | E22: JOD | G22: 26 | H22: 58 | I22: 65.5 | J22: 107 | K22: 0 | L22: 22.5 | M22: 29 | N22: 0 | O22: 6.5 | P22: 7.5 | Q22: 65.5
A23: Ashgabat, Turkmenistan | B23: Turkmenistan | C23: 3 | D23: TMT | E23: USD | F23: Y | G23: 45 | H23: 117.5 | I23: 143 | J23: 72.5 | K23: 0 | L23: 40 | M23: 67.5 | N23: 4 | O23: 10 | P23: 21.5 | Q23: 143
A24: Asmara, Eritrea | B24: Eritrea | C24: 3 | D24: ERN | E24: USD | F24: Y | G24: 363 | H24: 1084 | I24: 1295 | J24: 133.5 | K24: 0 | L24: 350 | M24: 708.5 | N24: 0 | O24: 25.5 | P24: 211 | Q24: 1295
A25: Astana, Kazakhstan | B25: Kazakhstan | C25: 3 | D25: USD | E25: USD | G25: 43 | H25: 120 | I25: 131 | J25: 263 | K25: 0 | L25: 35.5 | M25: 70 | N25: 4 | O25: 14.5 | P25: 7 | Q25: 131
A26: Athens, Greece | B26: Greece | C26: 1 | D26: EUR | E26: EUR | G26: 28.5 | H26: 62.5 | I26: 67.5 | J26: 153.5 | K26: 0 | L26: 25 | M26: 30.5 | N26: 0 | O26: 7 | P26: 5 | Q26: 67.5
A27: Atlanta, United States of America | B27: United States of America | C27: 4 | D27: USD | E27: USD | G27: 30.5 | H27: 75 | I27: 98.5 | J27: 127 | K27: 15 | L27: 27.5 | M27: 42 | N27: 0 | O27: 5.5 | P27: 8.5 | Q27: 98.5
A28: Atyrau, Kazakhstan | B28: Kazakhstan | C28: 3 | D28: KZT | E28: KZT | G28: 5234 | H28: 14591 | I28: 16227.5 | J28: 27595 | K28: 0 | L28: 4599.5 | M28: 8722.5 | N28: 634.5 | O28: 1269 | P28: 1002 | Q28: 16227.5
A29: Auckland, New Zealand | B29: New Zealand | C29: 6 | D29: NZD | E29: NZD | G29: 54 | H29: 133 | I29: 180.5 | J29: 205.5 | K29: 36 | L29: 48 | M29: 73.5 | N29: 0 | O29: 11.5 | P29: 11.5 | Q29: 180.5 | S29: Final day options
A30: Azores, Portugal | B30: Portugal | C30: 1 | D30: EUR | E30: EUR | G30: 16.5 | H30: 44.5 | I30: 49.5 | J30: 107 | K30: 0 | L30: 14 | M30: 26 | N30: 0 | O30: 4.5 | P30: 5 | Q30: 49.5 | S30: None
A31: Bahrain, Bahrain | B31: Bahrain | C31: 3 | D31: BHD | E31: BHD | G31: 17 | H31: 40.5 | I31: 56.5 | J31: 115.5 | K31: 13 | L31: 14.5 | M31: 21.5 | N31: 0 | O31: 4.5 | P31: 3 | Q31: 56.5 | S31: Over 5 hours
A32: Baku, Azerbaijan | B32: Azerbaijan | C32: 2 | D32: AZN | E32: AZN | G32: 31 | H32: 71 | I32: 85.5 | J32: 195 | K32: 0 | L32: 24.5 | M32: 34 | N32: 6 | O32: 12.5 | P32: 8.5 | Q32: 85.5 | S32: Over 10 hours
A33: Bamako, Mali | B33: Mali | C33: 3 | D33: XOF | E33: XOF | G33: 12241 | H33: 33940 | I33: 48629.5 | J33: 61759.5 | K33: 9459 | L33: 10571.5 | M33: 20030 | N33: 2003 | O33: 3338.5 | P33: 3227.5 | Q33: 48629.5
A34: Bandar Seri Begawan, Brunei | B34: Brunei | C34: 5 | D34: BND | E34: BND | G34: 37 | H34: 121.5 | I34: 134.5 | J34: 203 | K34: 0 | L34: 31 | M34: 79 | N34: 0 | O34: 11.5 | P34: 13 | Q34: 134.5
A35: Bangalore, India | B35: India | C35: 3 | D35: INR | E35: INR | G35: 1685.5 | H35: 3746 | I35: 4629.5 | J35: 16809.5 | K35: 0 | L35: 1406 | M35: 1781 | N35: 369 | O35: 559 | P35: 514.5 | Q35: 4629.5
A36: Bangkok, Thailand | B36: Thailand | C36: 4 | D36: THB | E36: THB | G36: 1048 | H36: 2565.5 | I36: 2965 | J36: 5442.5 | K36: 0 | L36: 884.5 | M36: 1354 | N36: 163.5 | O36: 327 | P36: 236 | Q36: 2965
A37: Banjul, Gambia | B37: Gambia | C37: 3 | D37: GMD | E37: EUR | F37: Y | G37: 531.5 | H37: 1485.5 | I37: 1860.5 | J37: 90 | K37: 0 | L37: 480.5 | M37: 903 | N37: 102 | O37: 102 | P37: 273 | Q37: 1860.5
A38: Barcelona, Spain | B38: Spain | C38: 1 | D38: EUR | E38: EUR | G38: 28 | H38: 76 | I38: 101.5 | J38: 176 | K38: 20 | L38: 24.5 | M38: 44.5 | N38: 0 | O38: 7 | P38: 5.5 | Q38: 101.5
A39: Basseterre, St Kitts and Nevis | B39: St Kitts and Nevis | C39: 4 | D39: XCD | E39: USD | F39: Y | G39: 94 | H39: 187 | I39: 250 | J39: 179 | K39: 41 | L39: 89.5 | M39: 88.5 | N39: 0 | O39: 9 | P39: 22 | Q39: 250
A40: Beijing, China | B40: China | C40: 4 | D40: CNY | E40: CNY | G40: 232 | H40: 563 | I40: 605.5 | J40: 1344.5 | K40: 0 | L40: 205 | M40: 304 | N40: 0 | O40: 54 | P40: 42.5 | Q40: 605.5
...

Sheet FX
A1: Exchange rates
A2: One row per currency in the HMRC rate data. Sterling costs are calculated as foreign amount ÷ budget rate.
A4: The market rate is fetched by STOCKHISTORY for the rate date set on the Trip plan. It needs a Microsoft 365 subscription and doesn't extend to all currencies. Where it is blank, type a market rate by hand and record where you got it (this will have the appropriate buffer applied).
A6: Currency | B6: Pair | C6: Trips in plan | D6: Market rate - fetched | E6: Buffer | F6: Market rate - typed | G6: Budget rate - used | H6: Source of the typed rate | I6: Basis
